Workbook

Sheet APROVADOS SEM FATURAMENTO
A1: Empresa | B1: Cliente | C1: Número Lote | D1: Produto P/ Faturamento | E1: Tipo Produto | F1: Produto | G1: Produto Comercial | H1: Peneira | I1: Campo | J1: Status | K1: Liberado Faturamento? | L1: Data Apontamento | M1: Data Produção | N1: Armazenado | O1: Data de Liberação | P1: Peso Impressão | Q1: Unidade de Medida | R1: Quantidade Lote | S1: Quantidade Apontada | T1: Qntd. Bloqueio Estoque | U1: Quantidade Faturada | V1: Saldo Lote | W1: Representatividade Sacos
A2: VALOREM - PATOS | B2: CORTEVA | C2: 05P7622449 | D2: PBT-P3845VYHR-R2 | E2: PBT - Produto Acabado em Big Bag Tratado | F2: P3845VYHR | G2: P3845VYHR | H2: R2 | I2: 7345816-434001 | J2: LOTE NÃO FATURADO | K2: Sim | L2: 23/09/2026 | M2: 23/09/2026 | N2: SIM | O2: 23/09/2026 | P2: 19.86 | Q2: BAG | R2: 15 | S2: 15 | T2: 0 | W2: 0.76
A3: VALOREM - PATOS | B3: CORTEVA | C3: 05P7622450 | D3: PBT-P3845VYHR-R2 | E3: PBT - Produto Acabado em Big Bag Tratado | F3: P3845VYHR | G3: P3845VYHR | H3: R2 | I3: 7345816-434001 | J3: LOTE NÃO FATURADO | K3: Sim | L3: 23/09/2026 | M3: 23/09/2026 | N3: SIM | O3: 23/09/2026 | P3: 19.69 | Q3: BAG | R3: 12 | S3: 12 | T3: 0 | W3: 0.61
A4: VALOREM - PATOS | B4: CORTEVA | C4: 05P7622451 | D4: PBT-P3845VYHR-R2 | E4: PBT - Produto Acabado em Big Bag Tratado | F4: P3845VYHR | G4: P3845VYHR | H4: R2 | I4: 7345816-434001 | J4: LOTE NÃO FATURADO | K4: Sim | L4: 24/09/2026 | M4: 24/09/2026 | N4: SIM | O4: 24/09/2026 | P4: 19.82 | Q4: BAG | R4: 10 | S4: 10 | T4: 0 | W4: 0.5
A5: VALOREM - PATOS | B5: CORTEVA | C5: 05P7622452 | D5: PBT-P3845VYHR-R2 | E5: PBT - Produto Acabado em Big Bag Tratado | F5: P3845VYHR | G5: P3845VYHR | H5: R2 | I5: 7345816-434001 | J5: LOTE NÃO FATURADO | K5: Sim | L5: 28/09/2026 | M5: 28/09/2026 | N5: SIM | O5: 28/09/2026 | P5: 19.65 | Q5: BAG | R5: 14 | S5: 14 | T5: 0 | W5: 0.71
A6: VALOREM - PATOS | B6: CORTEVA | C6: 05P7622468 | D6: PBT-P3845VYHR-R3 | E6: PBT - Produto Acabado em Big Bag Tratado | F6: P3845VYHR | G6: P3845VYHR | H6: R3 | I6: 7345816-434001 | J6: LOTE NÃO FATURADO | K6: Sim | L6: 23/09/2026 | M6: 23/09/2026 | N6: SIM | O6: 24/09/2026 | P6: 17.46 | Q6: BAG | R6: 13 | S6: 13 | T6: 0 | W6: 0.74
A7: VALOREM - PATOS | B7: CORTEVA | C7: 05P7622510 | D7: PBT-P3845VYHR-C1 | E7: PBT - Produto Acabado em Big Bag Tratado | F7: P3845VYHR | G7: P3845VYHR | H7: C1 | I7: 7345816-434001 | J7: LOTE NÃO FATURADO | K7: Sim | L7: 21/09/2026 | M7: 21/09/2026 | N7: SIM | O7: 22/09/2026 | P7: 20.23 | Q7: BAG | R7: 35 | S7: 35 | T7: 0 | W7: 1.73
A8: VALOREM - PATOS | B8: CORTEVA | C8: 05P7622511 | D8: PBT-P3845VYHR-C1 | E8: PBT - Produto Acabado em Big Bag Tratado | F8: P3845VYHR | G8: P3845VYHR | H8: C1 | I8: 7345816-434001 | J8: LOTE NÃO FATURADO | K8: Sim | L8: 22/09/2026 | M8: 22/09/2026 | N8: SIM | O8: 22/09/2026 | P8: 20.33 | Q8: BAG | R8: 32 | S8: 32 | T8: 0 | W8: 1.57
A9: VALOREM - PATOS | B9: CORTEVA | C9: 05P7622512 | D9: PBT-P3845VYHR-C1 | E9: PBT - Produto Acabado em Big Bag Tratado | F9: P3845VYHR | G9: P3845VYHR | H9: C1 | I9: 7345816-434001 | J9: LOTE NÃO FATURADO | K9: Sim | L9: 22/09/2026 | M9: 22/09/2026 | N9: SIM | O9: 23/09/2026 | P9: 20.22 | Q9: BAG | R9: 31 | S9: 31 | T9: 0 | W9: 1.53
A10: VALOREM - PATOS | B10: CORTEVA | C10: 05P7622513 | D10: PBT-P3845VYHR-C1 | E10: PBT - Produto Acabado em Big Bag Tratado | F10: P3845VYHR | G10: P3845VYHR | H10: C1 | I10: 7345816-434001 | J10: LOTE NÃO FATURADO | K10: Sim | L10: 23/09/2026 | M10: 23/09/2026 | N10: SIM | O10: 23/09/2026 | P10: 20.08 | Q10: BAG | R10: 23 | S10: 23 | T10: 0 | W10: 1.15
A11: VALOREM - PATOS | B11: CORTEVA | C11: 05P7622515 | D11: PBT-P3845VYHR-C1 | E11: PBT - Produto Acabado em Big Bag Tratado | F11: P3845VYHR | G11: P3845VYHR | H11: C1 | I11: 7345816-434001 | J11: LOTE NÃO FATURADO | K11: Sim | L11: 25/09/2026 | M11: 25/09/2026 | N11: SIM | O11: 28/09/2026 | P11: 19.8 | Q11: BAG | R11: 15 | S11: 15 | T11: 0 | W11: 0.76
A12: VALOREM - PATOS | B12: CORTEVA | C12: 05P7622520 | D12: PBT-P3845VYHR-C2 | E12: PBT - Produto Acabado em Big Bag Tratado | F12: P3845VYHR | G12: P3845VYHR | H12: C2 | I12: 7345816-434001 | J12: LOTE NÃO FATURADO | K12: Sim | L12: 21/09/2026 | M12: 21/09/2026 | N12: SIM | O12: 21/09/2026 | P12: 17.97 | Q12: BAG | R12: 13 | S12: 13 | T12: 0 | W12: 0.72
A13: VALOREM - PATOS | B13: CORTEVA | C13: 05P7622521 | D13: PBT-P3845VYHR-C2 | E13: PBT - Produto Acabado em Big Bag Tratado | F13: P3845VYHR | G13: P3845VYHR | H13: C2 | I13: 7345816-434001 | J13: LOTE NÃO FATURADO | K13: Sim | L13: 21/09/2026 | M13: 21/09/2026 | N13: SIM | O13: 21/09/2026 | P13: 18.01 | Q13: BAG | R13: 18 | S13: 18 | T13: 0 | W13: 1
... A49: VALOREM - PATOS | B49: CORTEVA | C49: 05P7643458 | D49: PAS-P3845VYHR-C2 | E49: PAS - Produto Acabado em Sacos | F49: P3845VYHR | G49: P3845VYHR | H49: C2 | I49: 7345816-434001 | J49: LOTE NÃO FATURADO | K49: Sem Registro | L49: 28/09/2026 | M49: 28/09/2026 | N49: SIM | O49: 29/09/2026 | P49: 17.78 | Q49: SC | R49: 3 | S49: 3 | T49: 0 | W49: 0.17

Sheet FATURAMENTO
A1: Empresa | B1: Cliente | C1: Produto | D1: Tipo de Produto | E1: Número Lote | F1: Unidade de Medida | G1: Status | H1: Data Apontamento | I1: Data Produção | J1: Data Liberação | K1: Data Faturamento | L1: Setor | M1: Local | N1: Linha | O1: Quantidade em Estoque
A2: VALOREM - PATOS | B2: CORTEVA | C2: P3889R | D2: PAS - Produto Acabado em Sacos | E2: 03P7609023 | F2: SC | G2: LOTE TOTALMENTE FATURADO | H2: 08/09/2026 | I2: 08/09/2026 | J2: 09/09/2026 | K2: 14/09/2026 | L2: ARMAZEM | M2: Camara Fria 2 | N2: CF2-02 | O2: 11
A3: VALOREM - PATOS | B3: CORTEVA | C3: P3889R | D3: PAS - Produto Acabado em Sacos | E3: 03P7609035 | F3: SC | G3: LOTE TOTALMENTE FATURADO | H3: 10/09/2026 | I3: 10/09/2026 | J3: 11/09/2026 | K3: 17/09/2026 | L3: ARMAZEM | M3: Camara Fria 2 | N3: CF2-02 | O3: 24
A4: VALOREM - PATOS | B4: CORTEVA | C4: P3889R | D4: PAS - Produto Acabado em Sacos | E4: 03P7609046 | F4: SC | G4: LOTE TOTALMENTE FATURADO | H4: 08/09/2026 | I4: 08/09/2026 | J4: 09/09/2026 | K4: 14/09/2026 | L4: ARMAZEM | M4: Camara Fria 2 | N4: CF2-02 | O4: 13
A5: VALOREM - PATOS | B5: CORTEVA | C5: P3889R | D5: PAS - Produto Acabado em Sacos | E5: 03P7609050 | F5: SC | G5: LOTE TOTALMENTE FATURADO | H5: 08/09/2026 | I5: 08/09/2026 | J5: 09/09/2026 | K5: 17/09/2026 | L5: ARMAZEM | M5: Camara Fria 2 | N5: CF2-02 | O5: 49
A6: VALOREM - PATOS | B6: CORTEVA | C6: P3889R | D6: PAS - Produto Acabado em Sacos | E6: 03P7609063 | F6: SC | G6: LOTE TOTALMENTE FATURADO | H6: 11/09/2026 | I6: 11/09/2026 | J6: 11/09/2026 | K6: 17/09/2026 | L6: ARMAZEM | M6: Camara Fria 2 | N6: CF2-02 | O6: 24
A7: VALOREM - PATOS | B7: CORTEVA | C7: P3889R | D7: PAS - Produto Acabado em Sacos | E7: 03P7609070 | F7: SC | G7: LOTE TOTALMENTE FATURADO | H7: 09/09/2026 | I7: 09/09/2026 | J7: 10/09/2026 | K7: 14/09/2026 | L7: ARMAZEM | M7: Camara Fria 2 | N7: CF2-02 | O7: 18
A8: VALOREM - PATOS | B8: CORTEVA | C8: P3889R | D8: PAS - Produto Acabado em Sacos | E8: 03P7609071 | F8: SC | G8: LOTE TOTALMENTE FATURADO | H8: 10/09/2026 | I8: 10/09/2026 | J8: 10/09/2026 | K8: 17/09/2026 | L8: ARMAZEM | M8: Camara Fria 2 | N8: CF2-02 | O8: 38
A9: VALOREM - PATOS | B9: CORTEVA | C9: P3889R | D9: PAS - Produto Acabado em Sacos | E9: 03P7609073 | F9: SC | G9: LOTE TOTALMENTE FATURADO | H9: 10/09/2026 | I9: 10/09/2026 | J9: 10/09/2026 | K9: 17/09/2026 | L9: ARMAZEM | M9: Camara Fria 2 | N9: CF2-02 | O9: 15
A10: VALOREM - PATOS | B10: CORTEVA | C10: P3889R | D10: PAS - Produto Acabado em Sacos | E10: 03P7609075 | F10: SC | G10: LOTE TOTALMENTE FATURADO | H10: 10/09/2026 | I10: 10/09/2026 | J10: 10/09/2026 | K10: 17/09/2026 | L10: ARMAZEM | M10: Camara Fria 2 | N10: CF2-02 | O10: 11
A11: VALOREM - PATOS | B11: CORTEVA | C11: P3889R | D11: PAS - Produto Acabado em Sacos | E11: 03P7609082 | F11: SC | G11: LOTE TOTALMENTE FATURADO | H11: 09/09/2026 | I11: 09/09/2026 | J11: 09/09/2026 | K11: 14/09/2026 | L11: ARMAZEM | M11: Camara Fria 2 | N11: CF2-02 | O11: 42
A12: VALOREM - PATOS | B12: CORTEVA | C12: P3889R | D12: PAS - Produto Acabado em Sacos | E12: 03P7609089 | F12: SC | G12: LOTE TOTALMENTE FATURADO | H12: 09/09/2026 | I12: 09/09/2026 | J12: 09/09/2026 | K12: 14/09/2026 | L12: ARMAZEM | M12: Camara Fria 2 | N12: CF2-02 | O12: 23
A13: VALOREM - PATOS | B13: CORTEVA | C13: P3889R | D13: PAS - Produto Acabado em Sacos | E13: 03P7609093 | F13: SC | G13: LOTE TOTALMENTE FATURADO | H13: 09/09/2026 | I13: 09/09/2026 | J13: 09/09/2026 | K13: 14/09/2026 | L13: ARMAZEM | M13: Camara Fria 2 | N13: CF2-02 | O13: 41
... A34: VALOREM - PATOS | B34: CORTEVA | C34: P3889R | D34: PBT - Produto Acabado em Big Bag Tratado | E34: 03P7600785 | F34: BAG | G34: LOTE TOTALMENTE FATURADO | H34: 10/09/2026 | I34: 10/09/2026 | J34: 11/09/2026 | K34: 17/09/2026 | L34: ARMAZEM | M34: Camara Fria 2 | N34: CF2-17 | O34: 17
A35: VALOREM - PATOS | B35: CORTEVA | C35: P3845VYHR | D35: PDB - Produto Debulhado em bag | E35: V1I6BC0043 | F35: KG | G35: LOTE PARCIALMENTE FATURADO | H35: 25/09/2026 | I35: 14/07/2026 | J35: 28/09/2026 | K35: 15/09/2026 | L35: TORRE | O35: 29727
A36: VALOREM - PATOS | B36: CORTEVA | C36: P3845VYHR | D36: PDB - Produto Debulhado em bag | E36: V1I6BC0043 | F36: KG | G36: LOTE PARCIALMENTE FATURADO | H36: 28/09/2026 | I36: 14/07/2026 | J36: 29/09/2026 | K36: 15/09/2026 | L36: ARMAZEM | O36: 2400
A37: VALOREM - PATOS | B37: CORTEVA | C37: P3845VYHR | D37: PDB - Produto Debulhado em bag | E37: V1I6BC0043 | F37: KG | G37: LOTE PARCIALMENTE FATURADO | H37: 28/09/2026 | I37: 14/07/2026 | J37: 29/09/2026 | K37: 15/09/2026 | L37: TORRE | O37: 43158
A38: VALOREM - PATOS | B38: CORTEVA | C38: P3845VYHR | D38: PDB - Produto Debulhado em bag | E38: V1I6BC0043 | F38: KG | G38: LOTE PARCIALMENTE FATURADO | H38: 29/09/2026 | I38: 14/07/2026 | J38: 30/09/2026 | K38: 15/09/2026 | L38: TORRE | O38: 46667
A39: VALOREM - PATOS | B39: CORTEVA | C39: P3845VYHR | D39: PDB - Produto Debulhado em bag | E39: V1I6BC0043 | F39: KG | G39: LOTE PARCIALMENTE FATURADO | H39: 30/09/2026 | I39: 14/07/2026 | J39: 30/09/2026 | K39: 15/09/2026 | L39: TORRE | O39: 3597
A40: VALOREM - PATOS | B40: CORTEVA | C40: P3845VYHR | D40: PDB - Produto Debulhado em bag | E40: V1I6BC0076 | F40: KG | G40: LOTE PARCIALMENTE FATURADO | H40: 30/09/2026 | I40: 28/08/2026 | J40: 30/09/2026 | K40: 15/09/2026 | L40: TORRE | O40: 42894
A41: VALOREM - PATOS | B41: CORTEVA | C41: P3845VYHR | D41: PDB - Produto Debulhado em bag | E41: V1I6BC0076 | F41: KG | G41: LOTE PARCIALMENTE FATURADO | H41: 30/09/2026 | I41: 28/08/2026 | J41: 30/09/2026 | K41: 15/09/2026 | L41: ARMAZEM | O41: 45982
A42: VALOREM - PATOS | B42: CORTEVA | C42: P3845VYHR | D42: PDB - Produto Debulhado em bag | E42: V1I6BC0084 | F42: KG | G42: LOTE PARCIALMENTE FATURADO | H42: 25/09/2026 | I42: 25/08/2026 | J42: 28/09/2026 | K42: 15/09/2026 | L42: TORRE | O42: 23384
A43: VALOREM - PATOS | B43: CORTEVA | C43: P3845VYHR | D43: PDB - Produto Debulhado em bag | E43: V1I6BC0084 | F43: KG | G43: LOTE PARCIALMENTE FATURADO | H43: 25/09/2026 | I43: 25/08/2026 | J43: 28/09/2026 | K43: 15/09/2026 | L43: TORRE | O43: 40468

Sheet ITEM ESTOQUE
A1: Empresa | B1: Cliente | C1: Produto | D1: Nome Comercial | E1: Número do Lote | F1: Campo | G1: Safra | H1: Peneira | I1: Tipo de Entrada | J1: Tipo de Produto | K1: Tipo de Tratamento | L1: Responsável Movto | M1: Setor | N1: Palete | O1: Quantidade | P1: Unidade Medida | Q1: Umidade | R1: Peso (Kg) | S1: Peso Líquido (Kg) | T1: Localização | U1: Localização Física | V1: Em movimentação? | W1: Último registro qualidade | X1: Liberado Qualidade? | Y1: Tipo movimentação | Z1: Controle Pátio | AA1: Ordem Expedição | AB1: Célula Secagem | AC1: Silo Destino | AD1: Dt. Movimentação | AE1: Dt. Fim Movimentação | AF1: Obs | AG1: Tipo Informativo | AH1: Número Informativo | AI1: Tipo Consumo | AJ1: Restrições MPB | AK1: Código do Bag
A2: VALOREM - PATOS | B2: CORTEVA | C2: MILHO EM GRAO DESTINADO A SEMENTE P3889R | D2: P3889R | E2: V3I6CC0330 | F2: 7359269-85902 | G2: INV26/26 | H2: C2 | I2: Informativo de ensaque de classificação | J2: PAB - Produto acabado em Bag | K2: PREVENTIVO | L2: LEANDRO MAGALHAES MULLER ROMAGNOLI | M2: TSI | N2: 0022810/26 | O2: 0 | P2: KG | R2: 3 | S2: 0 | V2: Não | W2: 1000 - Aprovação | X2: Sim | Y2: Fracionamento | AA2: 0 | AC2: N/A | AD2: 10/09/2026 11:15:37 | AF2: FRACIONADO PARA CONSUMO | AG2: Informativo de ensaque de classificação | AH2: null
A3: VALOREM - PATOS | B3: CORTEVA | C3: MILHO EM GRAO DESTINADO A SEMENTE P3889R | D3: P3889R | E3: V3I6CC0330 | F3: 7359269-85902 | G3: INV26/26 | H3: C2 | I3: Informativo de ensaque de classificação | J3: PAB - Produto acabado em Bag | K3: PREVENTIVO | L3: LEANDRO MAGALHAES MULLER ROMAGNOLI | M3: TSI | N3: 0022814/26 | O3: 224.4 | P3: KG | R3: 227.4 | S3: 224.4 | V3: Não | W3: 1000 - Aprovação | X3: Sim | Y3: Fracionamento | AA3: 0 | AC3: N/A | AD3: 10/09/2026 11:15:36 | AF3: FRACIONADO PARA CONSUMO | AG3: Informativo de ensaque de classificação | AH3: null
A4: VALOREM - PATOS | B4: CORTEVA | C4: SEMENTE DE MILHO HIBRIDO - P3889R R4 BB - | D4: P3889R | E4: 03P7600741 | F4: 7359269-85902 | G4: INV26/26 | H4: R4 | I4: Informativo de ensaque clean para PA | J4: PBT - Produto Acabado em Big Bag Tratado | K4: STANDARD + P + D + L + L | L4: JULIO CESAR VIEIRA SILVA | M4: ARMAZEM | N4: 0022900/26 | O4: 1 | P4: BAG | R4: 693.5 | S4: 687 | T4: Camara Fria 2 | U4: CF2-18 | V4: Não | W4: 1000 - Aprovação | X4: Sim | Y4: Alocação física | AA4: 0 | AC4: N/A | AD4: 15/09/2026 14:57:50 | AG4: Informativo de ensaque clean para PA | AH4: null | AK4: 599998926249
A5: VALOREM - PATOS | B5: CORTEVA | C5: SEMENTE DE MILHO HIBRIDO - P3889R R4 BB - | D5: P3889R | E5: 03P7600741 | F5: 7359269-85902 | G5: INV26/26 | H5: R4 | I5: Informativo de ensaque clean para PA | J5: PBT - Produto Acabado em Big Bag Tratado | K5: STANDARD + P + D + L + L | L5: JULIO CESAR VIEIRA SILVA | M5: ARMAZEM | N5: 0022902/26 | O5: 1 | P5: BAG | R5: 693.5 | S5: 687 | T5: Camara Fria 2 | U5: CF2-18 | V5: Sim | W5: 1000 - Aprovação | X5: Sim | Y5: Alocação física | AA5: 0 | AC5: N/A | AD5: 15/09/2026 14:57:19 | AG5: Informativo de ensaque clean para PA | AH5: null | AK5: 599998914534
A6: VALOREM - PATOS | B6: CORTEVA | C6: SEMENTE DE MILHO HIBRIDO - P3889R R4 BB - | D6: P3889R | E6: 03P7600741 | F6: 7359269-85902 | G6: INV26/26 | H6: R4 | I6: Informativo de ensaque clean para PA | J6: PBT - Produto Acabado em Big Bag Tratado | K6: STANDARD + P + D + L + L | L6: JULIO CESAR VIEIRA SILVA | M6: ARMAZEM | N6: 0022904/26 | O6: 1 | P6: BAG | R6: 693.5 | S6: 687 | T6: Camara Fria 2 | U6: CF2-18 | V6: Não | W6: 1000 - Aprovação | X6: Sim | Y6: Alocação física | AA6: 0 | AC6: N/A | AD6: 15/09/2026 14:57:54 | AG6: Informativo de ensaque clean para PA | AH6: null | AK6: 599998914504
A7: VALOREM - PATOS | B7: CORTEVA | C7: SEMENTE DE MILHO HIBRIDO - P3889R R4 BB - | D7: P3889R | E7: 03P7600741 | F7: 7359269-85902 | G7: INV26/26 | H7: R4 | I7: Informativo de ensaque clean para PA | J7: PBT - Produto Acabado em Big Bag Tratado | K7: STANDARD + P + D + L + L | L7: JULIO CESAR VIEIRA SILVA | M7: ARMAZEM | N7: 0022906/26 | O7: 1 | P7: BAG | R7: 689.5 | S7: 687 | T7: Camara Fria 2 | U7: CF2-18 | V7: Não | W7: 1000 - Aprovação | X7: Sim | Y7: Alocação física | AA7: 0 | AC7: N/A | AD7: 15/09/2026 14:57:59 | AG7: Informativo de ensaque clean para PA | AH7: null | AK7: 599998925605
A8: VALOREM - PATOS | B8: CORTEVA | C8: SEMENTE DE MILHO HIBRIDO - P3889R R4 BB - | D8: P3889R | E8: 03P7600741 | F8: 7359269-85902 | G8: INV26/26 | H8: R4 | I8: Informativo de ensaque clean para PA | J8: PBT - Produto Acabado em Big Bag Tratado | K8: STANDARD + P + D + L + L | L8: JULIO CESAR VIEIRA SILVA | M8: ARMAZEM | N8: 0022908/26 | O8: 1 | P8: BAG | R8: 693 | S8: 687 | T8: Camara Fria 2 | U8: CF2-18 | V8: Não | W8: 1000 - Aprovação | X8: Sim | Y8: Alocação física | AA8: 0 | AC8: N/A | AD8: 15/09/2026 14:58:03 | AG8: Informativo de ensaque clean para PA | AH8: null | AK8: 599999557567
A9: VALOREM - PATOS | B9: CORTEVA | C9: SEMENTE DE MILHO HIBRIDO - P3889R R4 BB - | D9: P3889R | E9: 03P7600741 | F9: 7359269-85902 | G9: INV26/26 | H9: R4 | I9: Informativo de ensaque clean para PA | J9: PBT - Produto Acabado em Big Bag Tratado | K9: STANDARD + P + D + L + L | L9: JULIO CESAR VIEIRA SILVA | M9: ARMAZEM | N9: 0022910/26 | O9: 1 | P9: BAG | R9: 693.5 | S9: 687 | T9: Camara Fria 2 | U9: CF2-18 | V9: Sim | W9: 1000 - Aprovação | X9: Sim | Y9: Alocação física | AA9: 0 | AC9: N/A | AD9: 15/09/2026 14:58:25 | AG9: Informativo de ensaque clean para PA | AH9: null | AK9: 599999562730
A10: VALOREM - PATOS | B10: CORTEVA | C10: SEMENTE DE MILHO HIBRIDO - P3889R R4 BB - | D10: P3889R | E10: 03P7600741 | F10: 7359269-85902 | G10: INV26/26 | H10: R4 | I10: Informativo de ensaque clean para PA | J10: PBT - Produto Acabado em Big Bag Tratado | K10: STANDARD + P + D + L + L | L10: JULIO CESAR VIEIRA SILVA | M10: ARMAZEM | N10: 0022912/26 | O10: 1 | P10: BAG | R10: 693.5 | S10: 687 | T10: Camara Fria 2 | U10: CF2-18 | V10: Sim | W10: 1000 - Aprovação | X10: Sim | Y10: Alocação física | AA10: 0 | AC10: N/A | AD10: 15/09/2026 14:58:10 | AG10: Informativo de ensaque clean para PA | AH10: null | AK10: 599999557568
A11: VALOREM - PATOS | B11: CORTEVA | C11: SEMENTE DE MILHO HIBRIDO - P3889R R4 BB - | D11: P3889R | E11: 03P7600741 | F11: 7359269-85902 | G11: INV26/26 | H11: R4 | I11: Informativo de ensaque clean para PA | J11: PBT - Produto Acabado em Big Bag Tratado | K11: STANDARD + P + D + L + L | L11: JULIO CESAR VIEIRA SILVA | M11: ARMAZEM | N11: 0022914/26 | O11: 1 | P11: BAG | R11: 693 | S11: 687 | T11: Camara Fria 2 | U11: CF2-18 | V11: Sim | W11: 1000 - Aprovação | X11: Sim | Y11: Alocação física | AA11: 0 | AC11: N/A | AD11: 15/09/2026 14:58:06 | AG11: Informativo de ensaque clean para PA | AH11: null | AK11: 599998925711
A12: VALOREM - PATOS | B12: CORTEVA | C12: SEMENTE DE MILHO HIBRIDO - P3889R R4 BB - | D12: P3889R | E12: 03P7600741 | F12: 7359269-85902 | G12: INV26/26 | H12: R4 | I12: Informativo de ensaque clean para PA | J12: PBT - Produto Acabado em Big Bag Tratado | K12: STANDARD + P + D + L + L | L12: JULIO CESAR VIEIRA SILVA | M12: ARMAZEM | N12: 0022917/26 | O12: 1 | P12: BAG | R12: 693.5 | S12: 687 | T12: Camara Fria 2 | U12: CF2-18 | V12: Não | W12: 1000 - Aprovação | X12: Sim | Y12: Alocação física | AA12: 0 | AC12: N/A | AD12: 15/09/2026 14:57:39 | AG12: Informativo de ensaque clean para PA | AH12: null | AK12: 599999557569
A13: VALOREM - PATOS | B13: CORTEVA | C13: SEMENTE DE MILHO HIBRIDO - P3889R R4 BB - | D13: P3889R | E13: 03P7600741 | F13: 7359269-85902 | G13: INV26/26 | H13: R4 | I13: Informativo de ensaque clean para PA | J13: PBT - Produto Acabado em Big Bag Tratado | K13: STANDARD + P + D + L + L | L13: JULIO CESAR VIEIRA SILVA | M13: ARMAZEM | N13: 0022919/26 | O13: 1 | P13: BAG | R13: 693.5 | S13: 687 | T13: Camara Fria 2 | U13: CF2-18 | V13: Não | W13: 1000 - Aprovação | X13: Sim | Y13: Alocação física | AA13: 0 | AC13: N/A | AD13: 15/09/2026 14:57:43 | AG13: Informativo de ensaque clean para PA | AH13: null | AK13: 599998926756
A14: VALOREM - PATOS | B14: CORTEVA | C14: SEMENTE DE MILHO HIBRIDO - P3889R R4 BB - | D14: P3889R | E14: 03P7600741 | F14: 7359269-85902 | G14: INV26/26 | H14: R4 | I14: Informativo de ensaque clean para PA | J14: PBT - Produto Acabado em Big Bag Tratado | K14: STANDARD + P + D + L + L | L14: JULIO CESAR VIEIRA SILVA | M14: ARMAZEM | N14: 0022921/26 | O14: 1 | P14: BAG | R14: 693.5 | S14: 687 | T14: Camara Fria 2 | U14: CF2-18 | V14: Não | W14: 1000 - Aprovação | X14: Sim | Y14: Alocação física | AA14: 0 | AC14: N/A | AD14: 15/09/2026 14:57:46 | AG14: Informativo de ensaque clean para PA | AH14: null | AK14: 599999562745
A15: VALOREM - PATOS | B15: CORTEVA | C15: SEMENTE DE MILHO HIBRIDO - P3889R R4 BB - | D15: P3889R | E15: 03P7600741 | F15: 7359269-85902 | G15: INV26/26 | H15: R4 | I15: Informativo de ensaque clean para PA | J15: PBT - Produto Acabado em Big Bag Tratado | K15: STANDARD + P + D + L + L | L15: JULIO CESAR VIEIRA SILVA | M15: ARMAZEM | N15: 0022923/26 | O15: 1 | P15: BAG | R15: 690 | S15: 687 | T15: Camara Fria 2 | U15: CF2-18 | V15: Não | W15: 1000 - Aprovação | X15: Sim | Y15: Alocação física | AA15: 0 | AC15: N/A | AD15: 15/09/2026 14:58:21 | AG15: Informativo de ensaque clean para PA | AH15: null | AK15: 599999562732
... A17: VALOREM - PATOS | B17: CORTEVA | C17: SEMENTE DE MILHO HIBRIDO - P3889R R4 BB - | D17: P3889R | E17: 03P7600741 | F17: 7359269-85902 | G17: INV26/26 | H17: R4 | I17: Informativo de ensaque clean para PA | J17: PBT - Produto Acabado em Big Bag Tratado | K17: STANDARD + P + D + L + L | L17: JULIO CESAR VIEIRA SILVA | M17: ARMAZEM | N17: 0022928/26 | O17: 1 | P17: BAG | R17: 693.5 | S17: 687 | T17: Camara Fria 2 | U17: CF2-18 | V17: Não | W17: 1000 - Aprovação | X17: Sim | Y17: Alocação física | AA17: 0 | AC17: N/A | AD17: 15/09/2026 14:58:13 | AG17: Informativo de ensaque clean para PA | AH17: null | AK17: 599999562719
A18: VALOREM - PATOS | B18: CORTEVA | C18: SEMENTE DE MILHO HIBRIDO - P3889R R4 60S - | D18: P3889R | E18: 03P7609023 | F18: 7359269-85902 | G18: INV26/26 | H18: R4 | I18: Informativo de ensaque clean para PA | J18: PAS - Produto Acabado em Sacos | K18: STANDARD + P + D + L + L | L18: RODRIGO SILVA | M18: ARMAZEM | N18: 0022931/26 | O18: 11 | P18: SC | R18: 182 | S18: 151.14 | T18: Camara Fria 2 | U18: CF2-02 | V18: Sim | W18: 1000 - Aprovação | X18: Sim | Y18: Recepção do lote | AA18: 0 | AC18: N/A | AD18: 08/09/2026 14:47:47 | AG18: Informativo de ensaque clean para PA | AH18: null
A19: VALOREM - PATOS | B19: CORTEVA | C19: SEMENTE DE MILHO HIBRIDO - P3889R R3C 60S - | D19: P3889R | E19: 03P7609117 | F19: 7359269-85902 | G19: INV26/26 | H19: R3C | I19: Informativo de ensaque clean para PA | J19: PAS - Produto Acabado em Sacos | K19: STANDARD + P + D + L + L | L19: RODRIGO SILVA | M19: ARMAZEM | N19: 0022958/26 | O19: 9 | P19: SC | R19: 159.5 | S19: 127.35 | T19: Camara Fria 2 | U19: CF2-02 | V19: Não | W19: 1000 - Aprovação | X19: Sim | Y19: Recepção do lote | AA19: 0 | AC19: N/A | AD19: 09/09/2026 08:21:46 | AG19: Informativo de ensaque clean para PA | AH19: null
A20: VALOREM - PATOS | B20: CORTEVA | C20: SEMENTE DE MILHO HIBRIDO - P3889R R3 BB - | D20: P3889R | E20: 03P7600705 | F20: 7359269-85902 | G20: INV26/26 | H20: R3 | I20: Informativo de ensaque clean para PA | J20: PBT - Produto Acabado em Big Bag Tratado | K20: STANDARD + P + D + L + L | L20: RODRIGO SILVA | M20: ARMAZEM | N20: 0022961/26 | O20: 1 | P20: BAG | R20: 767 | S20: 760 | T20: Camara Fria 2 | U20: CF2-10 | V20: Sim | W20: 1000 - Aprovação | X20: Sim | Y20: Recepção do lote | AA20: 0 | AC20: N/A | AD20: 09/09/2026 08:29:39 | AG20: Informativo de ensaque clean para PA | AH20: null | AK20: 599999562752
A21: VALOREM - PATOS | B21: CORTEVA | C21: SEMENTE DE MILHO HIBRIDO - P3889R R3 BB - | D21: P3889R | E21: 03P7600705 | F21: 7359269-85902 | G21: INV26/26 | H21: R3 | I21: Informativo de ensaque clean para PA | J21: PBT - Produto Acabado em Big Bag Tratado | K21: STANDARD + P + D + L + L | L21: RODRIGO SILVA | M21: ARMAZEM | N21: 0022963/26 | O21: 1 | P21: BAG | R21: 766.5 | S21: 760 | T21: Camara Fria 2 | U21: CF2-10 | V21: Sim | W21: 1000 - Aprovação | X21: Sim | Y21: Recepção do lote | AA21: 0 | AC21: N/A | AD21: 09/09/2026 08:32:19 | AG21: Informativo de ensaque clean para PA | AH21: null | AK21: 599999562726
A22: VALOREM - PATOS | B22: CORTEVA | C22: SEMENTE DE MILHO HIBRIDO - P3889R R3 BB - | D22: P3889R | E22: 03P7600705 | F22: 7359269-85902 | G22: INV26/26 | H22: R3 | I22: Informativo de ensaque clean para PA | J22: PBT - Produto Acabado em Big Bag Tratado | K22: STANDARD + P + D + L + L | L22: RODRIGO SILVA | M22: ARMAZEM | N22: 0022965/26 | O22: 1 | P22: BAG | R22: 764.5 | S22: 760 | T22: Camara Fria 2 | U22: CF2-10 | V22: Sim | W22: 1000 - Aprovação | X22: Sim | Y22: Recepção do lote | AA22: 0 | AC22: N/A | AD22: 09/09/2026 08:33:42 | AG22: Informativo de ensaque clean para PA | AH22: null | AK22: 599998925704
A23: VALOREM - PATOS | B23: CORTEVA | C23: SEMENTE DE MILHO HIBRIDO - P3889R R3 BB - | D23: P3889R | E23: 03P7600705 | F23: 7359269-85902 | G23: INV26/26 | H23: R3 | I23: Informativo de ensaque clean para PA | J23: PBT - Produto Acabado em Big Bag Tratado | K23: STANDARD + P + D + L + L | L23: RODRIGO SILVA | M23: ARMAZEM | N23: 0022967/26 | O23: 1 | P23: BAG | R23: 766 | S23: 760 | T23: Camara Fria 2 | U23: CF2-10 | V23: Sim | W23: 1000 - Aprovação | X23: Sim | Y23: Recepção do lote | AA23: 0 | AC23: N/A | AD23: 09/09/2026 08:34:15 | AG23: Informativo de ensaque clean para PA | AH23: null | AK23: 599999557578
A24: VALOREM - PATOS | B24: CORTEVA | C24: SEMENTE DE MILHO HIBRIDO - P3889R R3 BB - | D24: P3889R | E24: 03P7600705 | F24: 7359269-85902 | G24: INV26/26 | H24: R3 | I24: Informativo de ensaque clean para PA | J24: PBT - Produto Acabado em Big Bag Tratado | K24: STANDARD + P + D + L + L | L24: RODRIGO SILVA | M24: ARMAZEM | N24: 0022969/26 | O24: 1 | P24: BAG | R24: 762 | S24: 760 | T24: Camara Fria 2 | U24: CF2-10 | V24: Sim | W24: 1000 - Aprovação | X24: Sim | Y24: Recepção do lote | AA24: 0 | AC24: N/A | AD24: 09/09/2026 08:33:13 | AG24: Informativo de ensaque clean para PA | AH24: null | AK24: 599998925710
A25: VALOREM - PATOS | B25: CORTEVA | C25: SEMENTE DE MILHO HIBRIDO - P3889R R3 BB - | D25: P3889R | E25: 03P7600705 | F25: 7359269-85902 | G25: INV26/26 | H25: R3 | I25: Informativo de ensaque clean para PA | J25: PBT - Produto Acabado em Big Bag Tratado | K25: STANDARD + P + D + L + L | L25: RODRIGO SILVA | M25: ARMAZEM | N25: 0022971/26 | O25: 1 | P25: BAG | R25: 765.5 | S25: 760 | T25: Camara Fria 2 | U25: CF2-10 | V25: Sim | W25: 1000 - Aprovação | X25: Sim | Y25: Recepção do lote | AA25: 0 | AC25: N/A | AD25: 09/09/2026 08:34:53 | AG25: Informativo de ensaque clean para PA | AH25: null | AK25: 599999562737
A26: VALOREM - PATOS | B26: CORTEVA | C26: SEMENTE DE MILHO HIBRIDO - P3889R R3 BB - | D26: P3889R | E26: 03P7600705 | F26: 7359269-85902 | G26: INV26/26 | H26: R3 | I26: Informativo de ensaque clean para PA | J26: PBT - Produto Acabado em Big Bag Tratado | K26: STANDARD + P + D + L + L | L26: RODRIGO SILVA | M26: ARMAZEM | N26: 0022973/26 | O26: 1 | P26: BAG | R26: 766.5 | S26: 760 | T26: Camara Fria 2 | U26: CF2-10 | V26: Sim | W26: 1000 - Aprovação | X26: Sim | Y26: Recepção do lote | AA26: 0 | AC26: N/A | AD26: 09/09/2026 08:35:22 | AG26: Informativo de ensaque clean para PA | AH26: null | AK26: 599998925708
A27: VALOREM - PATOS | B27: CORTEVA | C27: SEMENTE DE MILHO HIBRIDO - P3889R R3 BB - | D27: P3889R | E27: 03P7600705 | F27: 7359269-85902 | G27: INV26/26 | H27: R3 | I27: Informativo de ensaque clean para PA | J27: PBT - Produto Acabado em Big Bag Tratado | K27: STANDARD + P + D + L + L | L27: RODRIGO SILVA | M27: ARMAZEM | N27: 0022975/26 | O27: 1 | P27: BAG | R27: 766 | S27: 760 | T27: Camara Fria 2 | U27: CF2-10 | V27: Sim | W27: 1000 - Aprovação | X27: Sim | Y27: Recepção do lote | AA27: 0 | AC27: N/A | AD27: 09/09/2026 08:36:42 | AG27: Informativo de ensaque clean para PA | AH27: null | AK27: 599999557570
A28: VALOREM - PATOS | B28: CORTEVA | C28: SEMENTE DE MILHO HIBRIDO - P3889R R3 BB - | D28: P3889R | E28: 03P7600705 | F28: 7359269-85902 | G28: INV26/26 | H28: R3 | I28: Informativo de ensaque clean para PA | J28: PBT - Produto Acabado em Big Bag Tratado | K28: STANDARD + P + D + L + L | L28: RODRIGO SILVA | M28: ARMAZEM | N28: 0022977/26 | O28: 1 | P28: BAG | R28: 761.5 | S28: 760 | T28: Camara Fria 2 | U28: CF2-10 | V28: Sim | W28: 1000 - Aprovação | X28: Sim | Y28: Recepção do lote | AA28: 0 | AC28: N/A | AD28: 09/09/2026 08:36:14 | AG28: Informativo de ensaque clean para PA | AH28: null | AK28: 599999557566
A29: VALOREM - PATOS | B29: CORTEVA | C29: SEMENTE DE MILHO HIBRIDO - P3889R R3 BB - | D29: P3889R | E29: 03P7600705 | F29: 7359269-85902 | G29: INV26/26 | H29: R3 | I29: Informativo de ensaque clean para PA | J29: PBT - Produto Acabado em Big Bag Tratado | K29: STANDARD + P + D + L + L | L29: RODRIGO SILVA | M29: ARMAZEM | N29: 0022979/26 | O29: 1 | P29: BAG | R29: 761.5 | S29: 760 | T29: Camara Fria 2 | U29: CF2-10 | V29: Sim | W29: 1000 - Aprovação | X29: Sim | Y29: Recepção do lote | AA29: 0 | AC29: N/A | AD29: 09/09/2026 08:37:41 | AG29: Informativo de ensaque clean para PA | AH29: null | AK29: 599998925706
A30: VALOREM - PATOS | B30: CORTEVA | C30: SEMENTE DE MILHO HIBRIDO - P3889R R3 BB - | D30: P3889R | E30: 03P7600705 | F30: 7359269-85902 | G30: INV26/26 | H30: R3 | I30: Informativo de ensaque clean para PA | J30: PBT - Produto Acabado em Big Bag Tratado | K30: STANDARD + P + D + L + L | L30: RODRIGO SILVA | M30: ARMAZEM | N30: 0022981/26 | O30: 1 | P30: BAG | R30: 760.5 | S30: 760 | T30: Camara Fria 2 | U30: CF2-10 | V30: Sim | W30: 1000 - Aprovação | X30: Sim | Y30: Recepção do lote | AA30: 0 | AC30: N/A | AD30: 09/09/2026 08:37:10 | AG30: Informativo de ensaque clean para PA | AH30: null | AK30: 599998914404
A31: VALOREM - PATOS | B31: CORTEVA | C31: SEMENTE DE MILHO HIBRIDO - P3889R R3 BB - | D31: P3889R | E31: 03P7600705 | F31: 7359269-85902 | G31: INV26/26 | H31: R3 | I31: Informativo de ensaque clean para PA | J31: PBT - Produto Acabado em Big Bag Tratado | K31: STANDARD + P + D + L + L | L31: RODRIGO SILVA | M31: ARMAZEM | N31: 0022983/26 | O31: 1 | P31: BAG | R31: 764.5 | S31: 760 | T31: Camara Fria 2 | U31: CF2-10 | V31: Sim | W31: 1000 - Aprovação | X31: Sim | Y31: Recepção do lote | AA31: 0 | AC31: N/A | AD31: 09/09/2026 08:38:09 | AG31: Informativo de ensaque clean para PA | AH31: null | AK31: 599998914518
... A36: VALOREM - PATOS | B36: CORTEVA | C36: SEMENTE DE MILHO HIBRIDO - P3889R R3 BB - | D36: P3889R | E36: 03P7600705 | F36: 7359269-85902 | G36: INV26/26 | H36: R3 | I36: Informativo de ensaque clean para PA | J36: PBT - Produto Acabado em Big Bag Tratado | K36: STANDARD + P + D + L + L | L36: RODRIGO SILVA | M36: ARMAZEM | N36: 0022993/26 | O36: 1 | P36: BAG | R36: 760 | S36: 760 | T36: Camara Fria 2 | U36: CF2-10 | V36: Sim | W36: 1000 - Aprovação | X36: Sim | Y36: Recepção do lote | AA36: 0 | AC36: N/A | AD36: 09/09/2026 08:30:06 | AG36: Informativo de ensaque clean para PA | AH36: null | AK36: 599998925198
A37: VALOREM - PATOS | B37: CORTEVA | C37: SEMENTE DE MILHO HIBRIDO - P3889R R3 60S - | D37: P3889R | E37: 03P7609046 | F37: 7359269-85902 | G37: INV26/26 | H37: R3 | I37: Informativo de ensaque clean para PA | J37: PAS - Produto Acabado em Sacos | K37: STANDARD + P + D + L + L | L37: RODRIGO SILVA | M37: ARMAZEM | N37: 0022995/26 | O37: 13 | P37: SC | R37: 229 | S37: 197.6 | T37: Camara Fria 2 | U37: CF2-02 | V37: Não | W37: 1000 - Aprovação | X37: Sim | Y37: Recepção do lote | AA37: 0 | AC37: N/A | AD37: 09/09/2026 08:24:21 | AG37: Informativo de ensaque clean para PA | AH37: null
A38: VALOREM - PATOS | B38: CORTEVA | C38: SEMENTE DE MILHO HIBRIDO - P3889R R3 BB - | D38: P3889R | E38: 03P7600730 | F38: 7359269-85902 | G38: INV26/26 | H38: R3 | I38: Informativo de ensaque clean para PA | J38: PBT - Produto Acabado em Big Bag Tratado | K38: STANDARD + P + D + L + L | L38: GUILHERME ALFENAS DE OLIVEIRA | M38: ARMAZEM | N38: 0023002/26 | O38: 1 | P38: BAG | R38: 753.5 | S38: 748.5 | T38: Camara Fria 2 | U38: CF2-28 | V38: Não | W38: 1000 - Aprovação | X38: Sim | Y38: Alocação física | AA38: 0 | AC38: N/A | AD38: 15/09/2026 14:55:36 | AG38: Informativo de ensaque clean para PA | AH38: null | AK38: 599999562705
A39: VALOREM - PATOS | B39: CORTEVA | C39: SEMENTE DE MILHO HIBRIDO - P3889R R3 BB - | D39: P3889R | E39: 03P7600730 | F39: 7359269-85902 | G39: INV26/26 | H39: R3 | I39: Informativo de ensaque clean para PA | J39: PBT - Produto Acabado em Big Bag Tratado | K39: STANDARD + P + D + L + L | L39: GUILHERME ALFENAS DE OLIVEIRA | M39: ARMAZEM | N39: 0023004/26 | O39: 1 | P39: BAG | R39: 749 | S39: 748.5 | T39: Camara Fria 2 | U39: CF2-28 | V39: Não | W39: 1000 - Aprovação | X39: Sim | Y39: Alocação física | AA39: 0 | AC39: N/A | AD39: 15/09/2026 14:55:21 | AG39: Informativo de ensaque clean para PA | AH39: null | AK39: 599999557572
A40: VALOREM - PATOS | B40: CORTEVA | C40: SEMENTE DE MILHO HIBRIDO - P3889R R3 BB - | D40: P3889R | E40: 03P7600730 | F40: 7359269-85902 | G40: INV26/26 | H40: R3 | I40: Informativo de ensaque clean para PA | J40: PBT - Produto Acabado em Big Bag Tratado | K40: STANDARD + P + D + L + L | L40: GUILHERME ALFENAS DE OLIVEIRA | M40: ARMAZEM | N40: 0023006/26 | O40: 1 | P40: BAG | R40: 752 | S40: 748.5 | T40: Camara Fria 2 | U40: CF2-28 | V40: Não | W40: 1000 - Aprovação | X40: Sim | Y40: Alocação física | AA40: 0 | AC40: N/A | AD40: 15/09/2026 14:55:45 | AG40: Informativo de ensaque clean para PA | AH40: null | AK40: 599998914486
A41: VALOREM - PATOS | B41: CORTEVA | C41: SEMENTE DE MILHO HIBRIDO - P3889R R3 BB - | D41: P3889R | E41: 03P7600730 | F41: 7359269-85902 | G41: INV26/26 | H41: R3 | I41: Informativo de ensaque clean para PA | J41: PBT - Produto Acabado em Big Bag Tratado | K41: STANDARD + P + D + L + L | L41: GUILHERME ALFENAS DE OLIVEIRA | M41: ARMAZEM | N41: 0023008/26 | O41: 1 | P41: BAG | R41: 750 | S41: 748.5 | T41: Camara Fria 2 | U41: CF2-28 | V41: Não | W41: 1000 - Aprovação | X41: Sim | Y41: Alocação física | AA41: 0 | AC41: N/A | AD41: 15/09/2026 14:56:50 | AG41: Informativo de ensaque clean para PA | AH41: null | AK41: 599999557526
A42: VALOREM - PATOS | B42: CORTEVA | C42: SEMENTE DE MILHO HIBRIDO - P3889R R3 BB - | D42: P3889R | E42: 03P7600730 | F42: 7359269-85902 | G42: INV26/26 | H42: R3 | I42: Informativo de ensaque clean para PA | J42: PBT - Produto Acabado em Big Bag Tratado | K42: STANDARD + P + D + L + L | L42: GUILHERME ALFENAS DE OLIVEIRA | M42: ARMAZEM | N42: 0023010/26 | O42: 1 | P42: BAG | R42: 753.5 | S42: 748.5 | T42: Camara Fria 2 | U42: CF2-28 | V42: Não | W42: 1000 - Aprovação | X42: Sim | Y42: Alocação física | AA42: 0 | AC42: N/A | AD42: 15/09/2026 14:56:43 | AG42: Informativo de ensaque clean para PA | AH42: null | AK42: 599999562735
A43: VALOREM - PATOS | B43: CORTEVA | C43: SEMENTE DE MILHO HIBRIDO - P3889R R3 BB - | D43: P3889R | E43: 03P7600730 | F43: 7359269-85902 | G43: INV26/26 | H43: R3 | I43: Informativo de ensaque clean para PA | J43: PBT - Produto Acabado em Big Bag Tratado | K43: STANDARD + P + D + L + L | L43: GUILHERME ALFENAS DE OLIVEIRA | M43: ARMAZEM | N43: 0023012/26 | O43: 1 | P43: BAG | R43: 750 | S43: 748.5 | T43: Camara Fria 2 | U43: CF2-28 | V43: Não | W43: 1000 - Aprovação | X43: Sim | Y43: Alocação física | AA43: 0 | AC43: N/A | AD43: 15/09/2026 14:56:54 | AG43: Informativo de ensaque clean para PA | AH43: null | AK43: 599999562731
A44: VALOREM - PATOS | B44: CORTEVA | C44: SEMENTE DE MILHO HIBRIDO - P3889R R3 BB - | D44: P3889R | E44: 03P7600730 | F44: 7359269-85902 | G44: INV26/26 | H44: R3 | I44: Informativo de ensaque clean para PA | J44: PBT - Produto Acabado em Big Bag Tratado | K44: STANDARD + P + D + L + L | L44: GUILHERME ALFENAS DE OLIVEIRA | M44: ARMAZEM | N44: 0023014/26 | O44: 1 | P44: BAG | R44: 753 | S44: 748.5 | T44: Camara Fria 2 | U44: CF2-28 | V44: Não | W44: 1000 - Aprovação | X44: Sim | Y44: Alocação física | AA44: 0 | AC44: N/A | AD44: 15/09/2026 14:56:46 | AG44: Informativo de ensaque clean para PA | AH44: null | AK44: 599999562692
A45: VALOREM - PATOS | B45: CORTEVA | C45: SEMENTE DE MILHO HIBRIDO - P3889R R3 BB - | D45: P3889R | E45: 03P7600730 | F45: 7359269-85902 | G45: INV26/26 | H45: R3 | I45: Informativo de ensaque clean para PA | J45: PBT - Produto Acabado em Big Bag Tratado | K45: STANDARD + P + D + L + L | L45: GUILHERME ALFENAS DE OLIVEIRA | M45: ARMAZEM | N45: 0023016/26 | O45: 1 | P45: BAG | R45: 753.5 | S45: 748.5 | T45: Camara Fria 2 | U45: CF2-28 | V45: Não | W45: 1000 - Aprovação | X45: Sim | Y45: Alocação física | AA45: 0 | AC45: N/A | AD45: 15/09/2026 14:57:01 | AG45: Informativo de ensaque clean para PA | AH45: null | AK45: 599998925717
...

Sheet DINÂMICA
A2: Localização Física | B2: (Tudo)
A3: Localização | B3: (Tudo) | F3: Rótulos de Linha | G3: Soma de Quantidade em Estoque
F4: (vazio)
A5: CLIENTE | B5: QUANTID. | C5: PALETES | D5: PESO LÍQUIDO | F5: (vazio)
A6: P3845VYHR | B6: 474968.95 | C6: 1008 | D6: 900890.2 | F6: CORTEVA | G6: 281312
A7: CORTEVA | B7: 474968.95 | C7: 1008 | D7: 900890.2 | F7: PAS - Produto Acabado em Sacos | G7: 2844
A8: PAB - Produto acabado em Bag | B8: 195633.95 | C8: 185 | D8: 195633.95 | F8: PBT - Produto Acabado em Big Bag Tratado | G8: 191
A9: PAS - Produto Acabado em Sacos | B9: 513 | C9: 25 | D9: 9694.85 | F9: PDB - Produto Debulhado em bag | G9: 278277
A10: PBT - Produto Acabado em Big Bag Tratado | B10: 545 | C10: 545 | D10: 417284.4 | F10: Total Geral | G10: 281312
A11: PDB - Produto Debulhado em bag | B11: 278277 | C11: 253 | D11: 278277
A12: P3889R | B12: 3259.4 | C12: 242 | D12: 175823.26 | F12: Liberado Faturamento? | G12: Sim
A13: CORTEVA | B13: 3259.4 | C13: 242 | D13: 175823.26
A14: PAB - Produto acabado em Bag | B14: 224.4 | C14: 2 | D14: 224.4 | F14: Rótulos de Linha | G14: Soma de Quantidade Apontada
A15: PAS - Produto Acabado em Sacos | B15: 2844 | C15: 49 | D15: 35744.36 | F15: CORTEVA | G15: 685
A16: PBT - Produto Acabado em Big Bag Tratado | B16: 191 | C16: 191 | D16: 139854.5 | F16: PAS - Produto Acabado em Sacos | G16: 367
A17: (vazio) | F17: PBT - Produto Acabado em Big Bag Tratado | G17: 318
A18: (vazio) | F18: Total Geral | G18: 685
A19: (vazio)
A20: Total Geral | B20: 478228.35 | C20: 1250 | D20: 1076713.5
F22: Liberado Faturamento? | G22: (Tudo)
F24: Rótulos de Linha | G24: Soma de Quantidade Apontada
F25: (vazio)
F26: (vazio)
F27: CORTEVA | G27: 979
F28: PAS - Produto Acabado em Sacos | G28: 450
F29: PBT - Produto Acabado em Big Bag Tratado | G29: 529
F30: Total Geral | G30: 979
A41: Localização Física | B41: (Vários itens)
A42: Localização | B42: (Vários itens)
A44: CLIENTE | B44: QUANTID. | C44: PALETES | D44: PESO LÍQUIDO
A45: CORTEVA | B45: 104742 | C45: 842 | D45: 655079.54
A46: P3845VYHR | B46: 101707 | C46: 602 | D46: 479480.68
A47: PAB - Produto acabado em Bag | B47: 100745 | C47: 92 | D47: 100745
A48: PAS - Produto Acabado em Sacos | B48: 476 | C48: 24 | D48: 8969.28
A49: PBT - Produto Acabado em Big Bag Tratado | B49: 486 | C49: 486 | D49: 369766.4
A50: P3889R | B50: 3035 | C50: 240 | D50: 175598.86
A51: PAS - Produto Acabado em Sacos | B51: 2844 | C51: 49 | D51: 35744.36
A52: PBT - Produto Acabado em Big Bag Tratado | B52: 191 | C52: 191 | D52: 139854.5
A53: Total Geral | B53: 104742 | C53: 842 | D53: 655079.54
A59: Localização Física | B59: (Vários itens)
...

Sheet RESUMO
B1: Geral | C1: Quantidade | D1: Unidade | E1: Peso líquido | F1: Total de Paletes | G1: Endereçado | H1: Não Endereçado | I1: Faturados | J1: Em Expedição | K1: OK P/ Faturar | L1: Liberado Qual. | M1: A Faturar Total | N1: TOTAL DE SACOS | O1: CF1 | P1: CF2
B2: Corteva
B3: PAS - Produto Acabado em Sacos | C3: =GETPIVOTDATA("QUANTID.",DINÂMICA!$A$5,"Cliente","CORTEVA","Nome Comercial","P3845VYHR","Tipo de Produto","PAS - Produto Acabado em Sacos")+GETPIVOTDATA("QUANTID.",DINÂMICA!$A$5,"Cliente","CORTEVA","Nome Comercial","P3889R","Tipo de Produto","PAS - Produto Acabado em Sacos") -> 3357 | D3: SACOS | E3: =GETPIVOTDATA("PESO LÍQUIDO",DINÂMICA!$A$5,"Cliente","CORTEVA","Nome Comercial","P3845VYHR","Tipo de Produto","PAS - Produto Acabado em Sacos")+GETPIVOTDATA("PESO LÍQUIDO",DINÂMICA!$A$5,"Cliente","CORTEVA","Nome Comercial","P3889R","Tipo de Produto","PAS - Produto Acabado em Sacos") -> 45439.21 | F3: =GETPIVOTDATA("PALETES",DINÂMICA!$A$5,"Cliente","CORTEVA","Nome Comercial","P3845VYHR","Tipo de Produto","PAS - Produto Acabado em Sacos")+GETPIVOTDATA("PALETES",DINÂMICA!$A$5,"Cliente","CORTEVA","Nome Comercial","P3889R","Tipo de Produto","PAS - Produto Acabado em Sacos") -> 74 | G3: =IFERROR(GETPIVOTDATA("QUANTID.",DINÂMICA!$A$44,"Cliente","CORTEVA","Nome Comercial","P3845VYHR","Tipo de Produto","PAS - Produto Acabado em Sacos")+GETPIVOTDATA("QUANTID.",DINÂMICA!$A$44,"Cliente","CORTEVA","Nome Comercial","P3889R","Tipo de Produto","PAS - Produto Acabado em Sacos"),0) -> 3320 | H3: =C3-G3 -> 37 | I3: =GETPIVOTDATA("Quantidade em Estoque",DINÂMICA!$F$3,"Cliente","CORTEVA","Tipo de Produto","PAS - Produto Acabado em Sacos") -> 2844 | J3: 2801 | K3: =IFERROR(GETPIVOTDATA("Quantidade Apontada",DINÂMICA!$F$14,"Cliente","CORTEVA","Tipo Produto","PAS - Produto Acabado em Sacos"),0) -> 367 | L3: =IFERROR(GETPIVOTDATA("Quantidade Apontada",DINÂMICA!$F$24,"Cliente","CORTEVA","Tipo Produto","PAS - Produto Acabado em Sacos"),0) -> 450 | M3: =C3-I3 -> 513 | N3: =C3 -> 3357 | O3: =GETPIVOTDATA("QUANTID.",DINÂMICA!$A$62,"Cliente","CORTEVA","Nome Comercial","P3845VYHR","Tipo de Produto","PAS - Produto Acabado em Sacos") -> 476 | P3: =GETPIVOTDATA("QUANTID.",DINÂMICA!$A$95,"Cliente","CORTEVA","Tipo de Produto","PAS - Produto Acabado em Sacos") -> 2844 | Q3: =(O3*O11)/O9 -> 0.00595
B4: PDB - Produto Debulhado em Bag | C4: =GETPIVOTDATA("QUANTID.",DINÂMICA!$A$5,"Cliente","CORTEVA","Nome Comercial","P3845VYHR","Tipo de Produto","PDB - Produto Debulhado em bag") -> 278277 | D4: KG | E4: =GETPIVOTDATA("PESO LÍQUIDO",DINÂMICA!$A$5,"Cliente","CORTEVA","Nome Comercial","P3845VYHR","Tipo de Produto","PDB - Produto Debulhado em bag") -> 278277 | F4: =GETPIVOTDATA("PALETES",DINÂMICA!$A$5,"Cliente","CORTEVA","Nome Comercial","P3845VYHR","Tipo de Produto","PDB - Produto Debulhado em bag") -> 253 | G4: 0 | H4: 0 | I4: 0 | N4: =F4*50 -> 12650
B5: PBT - Produto Acabado em Big Bag Tratado | C5: =GETPIVOTDATA("QUANTID.",DINÂMICA!$A$5,"Cliente","CORTEVA","Nome Comercial","P3845VYHR","Tipo de Produto","PBT - Produto Acabado em Big Bag Tratado")+GETPIVOTDATA("QUANTID.",DINÂMICA!$A$5,"Cliente","CORTEVA","Nome Comercial","P3889R","Tipo de Produto","PBT - Produto Acabado em Big Bag Tratado") -> 736 | D5: BAGS | E5: =GETPIVOTDATA("PESO LÍQUIDO",DINÂMICA!$A$5,"Cliente","CORTEVA","Nome Comercial","P3845VYHR","Tipo de Produto","PBT - Produto Acabado em Big Bag Tratado")+GETPIVOTDATA("PESO LÍQUIDO",DINÂMICA!$A$5,"Cliente","CORTEVA","Nome Comercial","P3889R","Tipo de Produto","PBT - Produto Acabado em Big Bag Tratado") -> 557138.9 | F5: =GETPIVOTDATA("PALETES",DINÂMICA!$A$5,"Cliente","CORTEVA","Nome Comercial","P3845VYHR","Tipo de Produto","PBT - Produto Acabado em Big Bag Tratado")+GETPIVOTDATA("PALETES",DINÂMICA!$A$5,"Cliente","CORTEVA","Nome Comercial","P3889R","Tipo de Produto","PBT - Produto Acabado em Big Bag Tratado") -> 736 | G5: =GETPIVOTDATA("PALETES",DINÂMICA!$A$44,"Cliente","CORTEVA","Nome Comercial","P3845VYHR","Tipo de Produto","PBT - Produto Acabado em Big Bag Tratado")+GETPIVOTDATA("PALETES",DINÂMICA!$A$44,"Cliente","CORTEVA","Nome Comercial","P3889R","Tipo de Produto","PBT - Produto Acabado em Big Bag Tratado") -> 677 | H5: =C5-G5 -> 59 | I5: =GETPIVOTDATA("Quantidade em Estoque",DINÂMICA!$F$3,"Cliente","CORTEVA","Tipo de Produto","PBT - Produto Acabado em Big Bag Tratado") -> 191 | J5: 191 | K5: =IFERROR(GETPIVOTDATA("Quantidade Apontada",DINÂMICA!$F$14,"Cliente","CORTEVA","Tipo Produto","PBT - Produto Acabado em Big Bag Tratado"),0) -> 318 | L5: =IFERROR(GETPIVOTDATA("Quantidade Apontada",DINÂMICA!$F$24,"Cliente","CORTEVA","Tipo Produto","PBT - Produto Acabado em Big Bag Tratado"),0) -> 529 | M5: =C5-I5 -> 545 | N5: =F5*40 -> 29440 | O5: =GETPIVOTDATA("QUANTID.",DINÂMICA!$A$62,"Cliente","CORTEVA","Nome Comercial","P3845VYHR","Tipo de Produto","PBT - Produto Acabado em Big Bag Tratado")*40 -> 19440 | P5: =GETPIVOTDATA("QUANTID.",DINÂMICA!$A$95,"Cliente","CORTEVA","Nome Comercial","P3889R","Tipo de Produto","PBT - Produto Acabado em Big Bag Tratado")*50 -> 9550 | Q5: =(O5*O11)/O9 -> 0.243 | R5: =I5*40 -> 7640
B6: PAB - Produto Acabado em Bag | C6: =GETPIVOTDATA("QUANTID.",DINÂMICA!$A$5,"Cliente","CORTEVA","Nome Comercial","P3845VYHR","Tipo de Produto","PAB - Produto acabado em Bag")+GETPIVOTDATA("QUANTID.",DINÂMICA!$A$5,"Cliente","CORTEVA","Nome Comercial","P3889R","Tipo de Produto","PAB - Produto acabado em Bag") -> 195858.35 | D6: KG | E6: =GETPIVOTDATA("PESO LÍQUIDO",DINÂMICA!$A$5,"Cliente","CORTEVA","Nome Comercial","P3845VYHR","Tipo de Produto","PAB - Produto acabado em Bag")+GETPIVOTDATA("PESO LÍQUIDO",DINÂMICA!$A$5,"Cliente","CORTEVA","Nome Comercial","P3889R","Tipo de Produto","PAB - Produto acabado em Bag") -> 195858.35 | F6: =IFERROR(GETPIVOTDATA("PALETES",DINÂMICA!$A$44,"Cliente","CORTEVA","Nome Comercial","P3845VYHR","Tipo de Produto","PAB - Produto acabado em Bag"),0) -> 92 | G6: =IFERROR(GETPIVOTDATA("QUANTID.",DINÂMICA!$A$44,"Cliente","CORTEVA","Tipo de Produto","PAB - Produto acabado em Bag"),0) -> 100745 | H6: =IFERROR(GETPIVOTDATA("Quantidade",DINÂMICA!$A$80,"Tipo de Produto","PAB - Produto acabado em Bag"),0) -> 18000 | I6: 0 | N6: =E6/17.5 -> 11191.906 | P6: =IFERROR(ROUNDUP(GETPIVOTDATA("QUANTID.",DINÂMICA!$A$95,"Cliente","CORTEVA","Tipo de Produto","PAB - Produto acabado em Bag")/17.5,0),0) -> 0
B7: Total | F7: =SUM(F2:F6) -> 1155
H8: DISPONIVEL CLIENTE: | I8: =I3-J3 -> 43 | J8: sacos
B9: Total em sacos | D9: =N9 -> 32310 | I9: =I5-J5 -> 0 | J9: bags | K9: =I9*40 -> 0 | N9: =SUM(O3:O7:P3:P7) -> 32310 | O9: =SUM(O3:O6) -> 19916 | P9: =SUM(P3:P6) -> 12394
B10: Capacidade total armazém | C10: 160000 | D10: 1
B11: Climatizado 01 | C11: 80000 | D11: =O11 -> 0.24895 | N11: =N9/N12 -> 0.2019375 | O11: =O9/O12 -> 0.24895 | P11: =P9/O12 -> 0.154925
B12: Climatizado 02 | C12: 80000 | D12: =P11 -> 0.154925 | N12: 160000 | O12: 80000
B13: Total Ocupado | D13: =D9/C10 -> 0.2019375
B15: Conversão de Clean pra PAS | D15: Sacos
B16: PAB - Produto Acabado em Bag | D16: =(SUM(G6)/17.5) -> 5756.8571
B17: PBT - Produto Acabado em Big Bag Tratado | D17: =GETPIVOTDATA("QUANTID.",DINÂMICA!$A$5,"Cliente","CORTEVA","Nome Comercial","P3845VYHR","Tipo de Produto","PBT - Produto Acabado em Big Bag Tratado")*40+GETPIVOTDATA("QUANTID.",DINÂMICA!$A$5,"Cliente","CORTEVA","Nome Comercial","P3889R","Tipo de Produto","PBT - Produto Acabado em Big Bag Tratado")*50 -> 31350
B18: PAS - Produto Acabado em Sacos | D18: =C3 -> 3357
D19: =SUM(D16:D18) -> 40463.857
B21: Expectativa de inicio em 26/08
B23: Projeção expedição - curva | D23: scs/veiculo | E23: saldo | F23: qtde. veículos
B24: PAS | D24: 1187 | E24: =SUM(I8,M3) -> 556 | F24: =ROUNDUP((E24)/D24,0) -> 1
B25: PBT | D25: 21 | E25: =SUM(I9,M5) -> 545 | F25: =ROUNDUP((E25)/D25,0) -> 26
F26: =SUM(F24:F25) -> 27
B28: CARGAS DIA | F28: 4
B29: DIAS DE EXPEDIÇÃO | F29: =ROUNDUP(F26/F28,0) -> 7

Sheet CARGAS
A1: Cronograma de Cargas Pendentes (Expectativa de 175k sacos)
A3: Premissas | B3: Valor | C3: Dias úteis necessários | D3: Data prevista de conclusão
A4: Data inicial | B4: 46260 | C4: =ROUNDUP(B5/B6,0) -> 48 | D4: =INDEX(F13:F67,MATCH(0,K13:K67,0)) -> 46336
A5: Total de veículos estimados | B5: =108+83 -> 191
A6: Cargas por dia útil | B6: 4
A7: Operação considerada | B7: Segunda a sexta
A8: Sábados, domingos e feriados | B8: Não considerados | F8: Data inicial | G8: =CARGAS!B4 -> 46260
F9: Cargas Estimadas | G9: =CARGAS!B5 -> 191
A10: Distribuição planejada por dia útil | F10: Cargas/dia | G10: =CARGAS!B6 -> 4
F11: Dias úteis previstos | G11: =ROUNDUP(G9/G10,0) -> 48
A12: Dia útil | B12: Data | C12: Veículos planejados | D12: Saldo final | F12: Data | G12: Dia da semana | H12: Dia útil nº | I12: Cargas planejadas | J12: Saldo inicial | K12: Saldo final | L12: Status | M12: Observações
A13: =CARGAS!H13 -> 1 | B13: =CARGAS!F13 -> 46260 | C13: =CARGAS!I13 -> 3 | D13: =CARGAS!K13 -> 188 | F13: =IF(CARGAS!$B$5<=0,"",CARGAS!$B$4) -> 46260 | G13: =IF(F13="","",TEXT(F13,"dddd")) -> quarta-feira | H13: =IF(F13="","",NETWORKDAYS(CARGAS!$B$4,F13)) -> 1 | I13: 3 | J13: =IF(F13="","",CARGAS!$B$5-SUM($I$12:I12)) -> 191 | K13: =IF(F13="","",MAX(0,J13-I13)) -> 188
A14: =CARGAS!H14 -> 2 | B14: =CARGAS!F14 -> 46261 | C14: =CARGAS!I14 -> 3 | D14: =CARGAS!K14 -> 185 | F14: =IFERROR(IF(K13>0,WORKDAY(F13,1),""),"") -> 46261 | G14: =IF(F14="","",TEXT(F14,"dddd")) -> quinta-feira | H14: =IF(F14="","",NETWORKDAYS(CARGAS!$B$4,F14)) -> 2 | I14: 3 | J14: =IF(F14="","",CARGAS!$B$5-SUM($I$12:I13)) -> 188 | K14: =IF(F14="","",MAX(0,J14-I14)) -> 185
A15: =CARGAS!H15 -> 3 | B15: =CARGAS!F15 -> 46262 | C15: =CARGAS!I15 -> 3 | D15: =CARGAS!K15 -> 182 | F15: =IFERROR(IF(K14>0,WORKDAY(F14,1),""),"") -> 46262 | G15: =IF(F15="","",TEXT(F15,"dddd")) -> sexta-feira | H15: =IF(F15="","",NETWORKDAYS(CARGAS!$B$4,F15)) -> 3 | I15: 3 | J15: =IF(F15="","",CARGAS!$B$5-SUM($I$12:I14)) -> 185 | K15: =IF(F15="","",MAX(0,J15-I15)) -> 182
A16: =CARGAS!H16 -> 4 | B16: =CARGAS!F16 -> 46265 | C16: =CARGAS!I16 -> 4 | D16: =CARGAS!K16 -> 178 | F16: =IFERROR(IF(K15>0,WORKDAY(F15,1),""),"") -> 46265 | G16: =IF(F16="","",TEXT(F16,"dddd")) -> segunda-feira | H16: =IF(F16="","",NETWORKDAYS(CARGAS!$B$4,F16)) -> 4 | I16: 4 | J16: =IF(F16="","",CARGAS!$B$5-SUM($I$12:I15)) -> 182 | K16: =IF(F16="","",MAX(0,J16-I16)) -> 178
A17: =CARGAS!H17 -> 5 | B17: =CARGAS!F17 -> 46266 | C17: =CARGAS!I17 -> 5 | D17: =CARGAS!K17 -> 173 | F17: =IFERROR(IF(K16>0,WORKDAY(F16,1),""),"") -> 46266 | G17: =IF(F17="","",TEXT(F17,"dddd")) -> terça-feira | H17: =IF(F17="","",NETWORKDAYS(CARGAS!$B$4,F17)) -> 5 | I17: 5 | J17: =IF(F17="","",CARGAS!$B$5-SUM($I$12:I16)) -> 178 | K17: =IF(F17="","",MAX(0,J17-I17)) -> 173
A18: =CARGAS!H18 -> 6 | B18: =CARGAS!F18 -> 46267 | C18: =CARGAS!I18 -> 3 | D18: =CARGAS!K18 -> 170 | F18: =IFERROR(IF(K17>0,WORKDAY(F17,1),""),"") -> 46267 | G18: =IF(F18="","",TEXT(F18,"dddd")) -> quarta-feira | H18: =IF(F18="","",NETWORKDAYS(CARGAS!$B$4,F18)) -> 6 | I18: 3 | J18: =IF(F18="","",CARGAS!$B$5-SUM($I$12:I17)) -> 173 | K18: =IF(F18="","",MAX(0,J18-I18)) -> 170
A19: =CARGAS!H19 -> 7 | B19: =CARGAS!F19 -> 46268 | C19: =CARGAS!I19 -> 4 | D19: =CARGAS!K19 -> 166 | F19: =IFERROR(IF(K18>0,WORKDAY(F18,1),""),"") -> 46268 | G19: =IF(F19="","",TEXT(F19,"dddd")) -> quinta-feira | H19: =IF(F19="","",NETWORKDAYS(CARGAS!$B$4,F19)) -> 7 | I19: 4 | J19: =IF(F19="","",CARGAS!$B$5-SUM($I$12:I18)) -> 170 | K19: =IF(F19="","",MAX(0,J19-I19)) -> 166
A20: =CARGAS!H20 -> 8 | B20: =CARGAS!F20 -> 46269 | C20: =CARGAS!I20 -> 0 | D20: =CARGAS!K20 -> 166 | F20: =IFERROR(IF(K19>0,WORKDAY(F19,1),""),"") -> 46269 | G20: =IF(F20="","",TEXT(F20,"dddd")) -> sexta-feira | H20: =IF(F20="","",NETWORKDAYS(CARGAS!$B$4,F20)) -> 8 | I20: 0 | J20: =IF(F20="","",CARGAS!$B$5-SUM($I$12:I19)) -> 166 | K20: =IF(F20="","",MAX(0,J20-I20)) -> 166
A21: =CARGAS!H21 -> 9 | B21: =CARGAS!F21 -> 46272 | C21: =CARGAS!I21 -> 0 | D21: =CARGAS!K21 -> 166 | F21: =IFERROR(IF(K20>0,WORKDAY(F20,1),""),"") -> 46272 | G21: =IF(F21="","",TEXT(F21,"dddd")) -> segunda-feira | H21: =IF(F21="","",NETWORKDAYS(CARGAS!$B$4,F21)) -> 9 | I21: 0 | J21: =IF(F21="","",CARGAS!$B$5-SUM($I$12:I20)) -> 166 | K21: =IF(F21="","",MAX(0,J21-I21)) -> 166
A22: =CARGAS!H22 -> 10 | B22: =CARGAS!F22 -> 46273 | C22: =CARGAS!I22 -> 5 | D22: =CARGAS!K22 -> 161 | F22: =IFERROR(IF(K21>0,WORKDAY(F21,1),""),"") -> 46273 | G22: =IF(F22="","",TEXT(F22,"dddd")) -> terça-feira | H22: =IF(F22="","",NETWORKDAYS(CARGAS!$B$4,F22)) -> 10 | I22: 5 | J22: =IF(F22="","",CARGAS!$B$5-SUM($I$12:I21)) -> 166 | K22: =IF(F22="","",MAX(0,J22-I22)) -> 161
A23: =CARGAS!H23 -> 11 | B23: =CARGAS!F23 -> 46274 | C23: =CARGAS!I23 -> 3 | D23: =CARGAS!K23 -> 158 | F23: =IFERROR(IF(K22>0,WORKDAY(F22,1),""),"") -> 46274 | G23: =IF(F23="","",TEXT(F23,"dddd")) -> quarta-feira | H23: =IF(F23="","",NETWORKDAYS(CARGAS!$B$4,F23)) -> 11 | I23: 3 | J23: =IF(F23="","",CARGAS!$B$5-SUM($I$12:I22)) -> 161 | K23: =IF(F23="","",MAX(0,J23-I23)) -> 158
A24: =CARGAS!H24 -> 12 | B24: =CARGAS!F24 -> 46275 | C24: =CARGAS!I24 -> 4 | D24: =CARGAS!K24 -> 154 | F24: =IFERROR(IF(K23>0,WORKDAY(F23,1),""),"") -> 46275 | G24: =IF(F24="","",TEXT(F24,"dddd")) -> quinta-feira | H24: =IF(F24="","",NETWORKDAYS(CARGAS!$B$4,F24)) -> 12 | I24: =IF(F24="","",MIN(CARGAS!$B$6,J24)) -> 4 | J24: =IF(F24="","",CARGAS!$B$5-SUM($I$12:I23)) -> 158 | K24: =IF(F24="","",MAX(0,J24-I24)) -> 154
A25: =CARGAS!H25 -> 13 | B25: =CARGAS!F25 -> 46276 | C25: =CARGAS!I25 -> 4 | D25: =CARGAS!K25 -> 150 | F25: =IFERROR(IF(K24>0,WORKDAY(F24,1),""),"") -> 46276 | G25: =IF(F25="","",TEXT(F25,"dddd")) -> sexta-feira | H25: =IF(F25="","",NETWORKDAYS(CARGAS!$B$4,F25)) -> 13 | I25: =IF(F25="","",MIN(CARGAS!$B$6,J25)) -> 4 | J25: =IF(F25="","",CARGAS!$B$5-SUM($I$12:I24)) -> 154 | K25: =IF(F25="","",MAX(0,J25-I25)) -> 150
A26: =CARGAS!H26 -> 14 | B26: =CARGAS!F26 -> 46279 | C26: =CARGAS!I26 -> 4 | D26: =CARGAS!K26 -> 146 | F26: =IFERROR(IF(K25>0,WORKDAY(F25,1),""),"") -> 46279 | G26: =IF(F26="","",TEXT(F26,"dddd")) -> segunda-feira | H26: =IF(F26="","",NETWORKDAYS(CARGAS!$B$4,F26)) -> 14 | I26: =IF(F26="","",MIN(CARGAS!$B$6,J26)) -> 4 | J26: =IF(F26="","",CARGAS!$B$5-SUM($I$12:I25)) -> 150 | K26: =IF(F26="","",MAX(0,J26-I26)) -> 146
A27: =CARGAS!H27 -> 15 | B27: =CARGAS!F27 -> 46280 | C27: =CARGAS!I27 -> 4 | D27: =CARGAS!K27 -> 142 | F27: =IFERROR(IF(K26>0,WORKDAY(F26,1),""),"") -> 46280 | G27: =IF(F27="","",TEXT(F27,"dddd")) -> terça-feira | H27: =IF(F27="","",NETWORKDAYS(CARGAS!$B$4,F27)) -> 15 | I27: =IF(F27="","",MIN(CARGAS!$B$6,J27)) -> 4 | J27: =IF(F27="","",CARGAS!$B$5-SUM($I$12:I26)) -> 146 | K27: =IF(F27="","",MAX(0,J27-I27)) -> 142
A28: =CARGAS!H28 -> 16 | B28: =CARGAS!F28 -> 46281 | C28: =CARGAS!I28 -> 4 | D28: =CARGAS!K28 -> 138 | F28: =IFERROR(IF(K27>0,WORKDAY(F27,1),""),"") -> 46281 | G28: =IF(F28="","",TEXT(F28,"dddd")) -> quarta-feira | H28: =IF(F28="","",NETWORKDAYS(CARGAS!$B$4,F28)) -> 16 | I28: =IF(F28="","",MIN(CARGAS!$B$6,J28)) -> 4 | J28: =IF(F28="","",CARGAS!$B$5-SUM($I$12:I27)) -> 142 | K28: =IF(F28="","",MAX(0,J28-I28)) -> 138
A29: =CARGAS!H29 -> 17 | B29: =CARGAS!F29 -> 46282 | C29: =CARGAS!I29 -> 4 | D29: =CARGAS!K29 -> 134 | F29: =IFERROR(IF(K28>0,WORKDAY(F28,1),""),"") -> 46282 | G29: =IF(F29="","",TEXT(F29,"dddd")) -> quinta-feira | H29: =IF(F29="","",NETWORKDAYS(CARGAS!$B$4,F29)) -> 17 | I29: =IF(F29="","",MIN(CARGAS!$B$6,J29)) -> 4 | J29: =IF(F29="","",CARGAS!$B$5-SUM($I$12:I28)) -> 138 | K29: =IF(F29="","",MAX(0,J29-I29)) -> 134
A30: =CARGAS!H30 -> 18 | B30: =CARGAS!F30 -> 46283 | C30: =CARGAS!I30 -> 5 | D30: =CARGAS!K30 -> 129 | F30: =IFERROR(IF(K29>0,WORKDAY(F29,1),""),"") -> 46283 | G30: =IF(F30="","",TEXT(F30,"dddd")) -> sexta-feira | H30: =IF(F30="","",NETWORKDAYS(CARGAS!$B$4,F30)) -> 18 | I30: 5 | J30: =IF(F30="","",CARGAS!$B$5-SUM($I$12:I29)) -> 134 | K30: =IF(F30="","",MAX(0,J30-I30)) -> 129
A31: =CARGAS!H31 -> 19 | B31: =CARGAS!F31 -> 46286 | C31: =CARGAS!I31 -> 4 | D31: =CARGAS!K31 -> 125 | F31: =IFERROR(IF(K30>0,WORKDAY(F30,1),""),"") -> 46286 | G31: =IF(F31="","",TEXT(F31,"dddd")) -> segunda-feira | H31: =IF(F31="","",NETWORKDAYS(CARGAS!$B$4,F31)) -> 19 | I31: =IF(F31="","",MIN(CARGAS!$B$6,J31)) -> 4 | J31: =IF(F31="","",CARGAS!$B$5-SUM($I$12:I30)) -> 129 | K31: =IF(F31="","",MAX(0,J31-I31)) -> 125
A32: =CARGAS!H32 -> 20 | B32: =CARGAS!F32 -> 46287 | C32: =CARGAS!I32 -> 4 | D32: =CARGAS!K32 -> 121 | F32: =IFERROR(IF(K31>0,WORKDAY(F31,1),""),"") -> 46287 | G32: =IF(F32="","",TEXT(F32,"dddd")) -> terça-feira | H32: =IF(F32="","",NETWORKDAYS(CARGAS!$B$4,F32)) -> 20 | I32: =IF(F32="","",MIN(CARGAS!$B$6,J32)) -> 4 | J32: =IF(F32="","",CARGAS!$B$5-SUM($I$12:I31)) -> 125 | K32: =IF(F32="","",MAX(0,J32-I32)) -> 121
A33: =CARGAS!H33 -> 21 | B33: =CARGAS!F33 -> 46288 | C33: =CARGAS!I33 -> 4 | D33: =CARGAS!K33 -> 117 | F33: =IFERROR(IF(K32>0,WORKDAY(F32,1),""),"") -> 46288 | G33: =IF(F33="","",TEXT(F33,"dddd")) -> quarta-feira | H33: =IF(F33="","",NETWORKDAYS(CARGAS!$B$4,F33)) -> 21 | I33: =IF(F33="","",MIN(CARGAS!$B$6,J33)) -> 4 | J33: =IF(F33="","",CARGAS!$B$5-SUM($I$12:I32)) -> 121 | K33: =IF(F33="","",MAX(0,J33-I33)) -> 117
A34: =CARGAS!H34 -> 22 | B34: =CARGAS!F34 -> 46289 | C34: =CARGAS!I34 -> 4 | D34: =CARGAS!K34 -> 113 | F34: =IFERROR(IF(K33>0,WORKDAY(F33,1),""),"") -> 46289 | G34: =IF(F34="","",TEXT(F34,"dddd")) -> quinta-feira | H34: =IF(F34="","",NETWORKDAYS(CARGAS!$B$4,F34)) -> 22 | I34: =IF(F34="","",MIN(CARGAS!$B$6,J34)) -> 4 | J34: =IF(F34="","",CARGAS!$B$5-SUM($I$12:I33)) -> 117 | K34: =IF(F34="","",MAX(0,J34-I34)) -> 113
A35: =CARGAS!H35 -> 23 | B35: =CARGAS!F35 -> 46290 | C35: =CARGAS!I35 -> 4 | D35: =CARGAS!K35 -> 109 | F35: =IFERROR(IF(K34>0,WORKDAY(F34,1),""),"") -> 46290 | G35: =IF(F35="","",TEXT(F35,"dddd")) -> sexta-feira | H35: =IF(F35="","",NETWORKDAYS(CARGAS!$B$4,F35)) -> 23 | I35: =IF(F35="","",MIN(CARGAS!$B$6,J35)) -> 4 | J35: =IF(F35="","",CARGAS!$B$5-SUM($I$12:I34)) -> 113 | K35: =IF(F35="","",MAX(0,J35-I35)) -> 109
A36: =CARGAS!H36 -> 24 | B36: =CARGAS!F36 -> 46293 | C36: =CARGAS!I36 -> 4 | D36: =CARGAS!K36 -> 105 | F36: =IFERROR(IF(K35>0,WORKDAY(F35,1),""),"") -> 46293 | G36: =IF(F36="","",TEXT(F36,"dddd")) -> segunda-feira | H36: =IF(F36="","",NETWORKDAYS(CARGAS!$B$4,F36)) -> 24 | I36: =IF(F36="","",MIN(CARGAS!$B$6,J36)) -> 4 | J36: =IF(F36="","",CARGAS!$B$5-SUM($I$12:I35)) -> 109 | K36: =IF(F36="","",MAX(0,J36-I36)) -> 105
A37: =CARGAS!H37 -> 25 | B37: =CARGAS!F37 -> 46294 | C37: =CARGAS!I37 -> 4 | D37: =CARGAS!K37 -> 101 | F37: =IFERROR(IF(K36>0,WORKDAY(F36,1),""),"") -> 46294 | G37: =IF(F37="","",TEXT(F37,"dddd")) -> terça-feira | H37: =IF(F37="","",NETWORKDAYS(CARGAS!$B$4,F37)) -> 25 | I37: =IF(F37="","",MIN(CARGAS!$B$6,J37)) -> 4 | J37: =IF(F37="","",CARGAS!$B$5-SUM($I$12:I36)) -> 105 | K37: =IF(F37="","",MAX(0,J37-I37)) -> 101
A38: =CARGAS!H38 -> 26 | B38: =CARGAS!F38 -> 46295 | C38: =CARGAS!I38 -> 4 | D38: =CARGAS!K38 -> 97 | F38: =IFERROR(IF(K37>0,WORKDAY(F37,1),""),"") -> 46295 | G38: =IF(F38="","",TEXT(F38,"dddd")) -> quarta-feira | H38: =IF(F38="","",NETWORKDAYS(CARGAS!$B$4,F38)) -> 26 | I38: =IF(F38="","",MIN(CARGAS!$B$6,J38)) -> 4 | J38: =IF(F38="","",CARGAS!$B$5-SUM($I$12:I37)) -> 101 | K38: =IF(F38="","",MAX(0,J38-I38)) -> 97
A39: =CARGAS!H39 -> 27 | B39: =CARGAS!F39 -> 46296 | C39: =CARGAS!I39 -> 4 | D39: =CARGAS!K39 -> 93 | F39: =IFERROR(IF(K38>0,WORKDAY(F38,1),""),"") -> 46296 | G39: =IF(F39="","",TEXT(F39,"dddd")) -> quinta-feira | H39: =IF(F39="","",NETWORKDAYS(CARGAS!$B$4,F39)) -> 27 | I39: =IF(F39="","",MIN(CARGAS!$B$6,J39)) -> 4 | J39: =IF(F39="","",CARGAS!$B$5-SUM($I$12:I38)) -> 97 | K39: =IF(F39="","",MAX(0,J39-I39)) -> 93
A40: =CARGAS!H40 -> 28 | B40: =CARGAS!F40 -> 46297 | C40: =CARGAS!I40 -> 4 | D40: =CARGAS!K40 -> 89 | F40: =IFERROR(IF(K39>0,WORKDAY(F39,1),""),"") -> 46297 | G40: =IF(F40="","",TEXT(F40,"dddd")) -> sexta-feira | H40: =IF(F40="","",NETWORKDAYS(CARGAS!$B$4,F40)) -> 28 | I40: =IF(F40="","",MIN(CARGAS!$B$6,J40)) -> 4 | J40: =IF(F40="","",CARGAS!$B$5-SUM($I$12:I39)) -> 93 | K40: =IF(F40="","",MAX(0,J40-I40)) -> 89
A41: =CARGAS!H41 -> 29 | B41: =CARGAS!F41 -> 46300 | C41: =CARGAS!I41 -> 4 | D41: =CARGAS!K41 -> 85 | F41: =IFERROR(IF(K40>0,WORKDAY(F40,1),""),"") -> 46300 | G41: =IF(F41="","",TEXT(F41,"dddd")) -> segunda-feira | H41: =IF(F41="","",NETWORKDAYS(CARGAS!$B$4,F41)) -> 29 | I41: =IF(F41="","",MIN(CARGAS!$B$6,J41)) -> 4 | J41: =IF(F41="","",CARGAS!$B$5-SUM($I$12:I40)) -> 89 | K41: =IF(F41="","",MAX(0,J41-I41)) -> 85
...

Sheet !CACHE! DO NOT EDIT THIS SHEET!
A1: Key | B1: TTL | C1: Model | D1: System Role | E1: Temperature | F1: Max tokens | G1: Response
