Workbook

Sheet _Shipments_BKP
A1: Data | B1: Shipment | C1: Delivery | D1: Item | E1: Material | F1: Qtd. | G1: Descr. Cliente | H1: Cidade | I1: Estado | J1: Qtde. Sel. | K1: Lote | L1: CLN | M1: Peneira | N1: Sacos total (Jumbo Convertidos) | O1: Qtde. sacos/palete | P1: Embalagem | Q1: Peso | R1: Qtde. Total de Paletes | S1: Motorista | T1: Telefone | U1: Placa Cavalo | V1: Placa Carreta | W1: Transportadora | Y1: Parâmetros
A2: =_xlfn.XLOOKUP(_Shipments[[#This Row],[Shipment]],[1]Report!$G:$G,[1]Report!$B:$B,"-") -> 46260.333 | B2: 7240103 | C2: 5541981925 | D2: 1 | E2: P3845VYHR-B822 | F2: 987 | G2: CORTEVA AGRISCIENCE DO BRASIL LTDA. | H2: APARECIDA DE GOIÂNIA | I2: GO | J2: 987 | K2: 7520918 | L2: 03P7520918 | M2: C3 | N2: =IF(_Shipments[[#This Row],[Embalagem]]="Big Bag",_Shipments[[#This Row],[Qtd.]]*_Shipments[[#This Row],[Qtde. sacos/palete]],_Shipments[[#This Row],[Qtd.]]) -> 987 | O2: =_xlfn.XLOOKUP(_Shipments[[#This Row],[CLN]],[2]Dados!$D:$D,[2]Dados!$R:$R,"-") -> 75 | P2: {=_xlfn.LET(_xlpm.t,_xlfn.XLOOKUP(_Shipments[[#This Row],[CLN]],[2]Dados!$D:$D,[2]Dados!$Q:$Q,"-"),_xlfn.IFS(LEFT(_xlpm.t,3)="PAS","Saco",LEFT(_xlpm.t,3)="PBT","Big Bag",TRUE,"-"))} -> Saco | Q2: =_xlfn.LET(_xlpm.p,_xlfn.XLOOKUP(_Shipments[[#This Row],[CLN]],[2]Dados!$D:$D,[2]Dados!$K:$K,"-"),_xlpm.n,_Shipments[[#This Row],[Qtde. sacos/palete]],IF(ISNUMBER(_xlpm.p),IF(_Shipments[[#This Row],[Embalagem]]="Big Bag",IF(ISNUMBER(_xlpm.n),_xlpm.p*_xlpm.n,"-"),_xlpm.p),"-")) -> 12.16 | R2: =IF(_Shipments[[#This Row],[Embalagem]]="Big Bag",_Shipments[[#This Row],[Qtd.]],ROUNDUP(_Shipments[[#This Row],[Qtd.]]/_Shipments[[#This Row],[Qtde. sacos/palete]],0)) -> 14 | S2: ECIO CRISTINO FERREIRA | T2: 34992119997 | U2: QDC-5910 | V2: HJC-1938 | W2: G10 TRANSPORTES S.A | Y2: 7240103
A3: =_xlfn.XLOOKUP(_Shipments[[#This Row],[Shipment]],[1]Report!$G:$G,[1]Report!$B:$B,"-") -> 46260.333 | B3: 7240103 | C3: 5541981925 | D3: 2 | E3: P3845VYHR-B825 | F3: 36 | G3: CORTEVA AGRISCIENCE DO BRASIL LTDA. | H3: APARECIDA DE GOIÂNIA | I3: GO | J3: 36 | K3: 7520947 | L3: 03P7520947 | M3: R3 | N3: =IF(_Shipments[[#This Row],[Embalagem]]="Big Bag",_Shipments[[#This Row],[Qtd.]]*_Shipments[[#This Row],[Qtde. sacos/palete]],_Shipments[[#This Row],[Qtd.]]) -> 36 | O3: =_xlfn.XLOOKUP(_Shipments[[#This Row],[CLN]],[2]Dados!$D:$D,[2]Dados!$R:$R,"-") -> 70 | P3: {=_xlfn.LET(_xlpm.t,_xlfn.XLOOKUP(_Shipments[[#This Row],[CLN]],[2]Dados!$D:$D,[2]Dados!$Q:$Q,"-"),_xlfn.IFS(LEFT(_xlpm.t,3)="PAS","Saco",LEFT(_xlpm.t,3)="PBT","Big Bag",TRUE,"-"))} -> Saco | Q3: =_xlfn.LET(_xlpm.p,_xlfn.XLOOKUP(_Shipments[[#This Row],[CLN]],[2]Dados!$D:$D,[2]Dados!$K:$K,"-"),_xlpm.n,_Shipments[[#This Row],[Qtde. sacos/palete]],IF(ISNUMBER(_xlpm.p),IF(_Shipments[[#This Row],[Embalagem]]="Big Bag",IF(ISNUMBER(_xlpm.n),_xlpm.p*_xlpm.n,"-"),_xlpm.p),"-")) -> 13.77 | R3: =IF(_Shipments[[#This Row],[Embalagem]]="Big Bag",_Shipments[[#This Row],[Qtd.]],ROUNDUP(_Shipments[[#This Row],[Qtd.]]/_Shipments[[#This Row],[Qtde. sacos/palete]],0)) -> 1 | S3: ECIO CRISTINO FERREIRA | T3: 34992119997 | U3: QDC-5910 | V3: HJC-1938 | W3: G10 TRANSPORTES S.A | Y3: 7240104
A4: =_xlfn.XLOOKUP(_Shipments[[#This Row],[Shipment]],[1]Report!$G:$G,[1]Report!$B:$B,"-") -> 46260.333 | B4: 7240103 | C4: 5541981925 | D4: 3 | E4: P3845VYHR-B824 | F4: 16 | G4: CORTEVA AGRISCIENCE DO BRASIL LTDA. | H4: APARECIDA DE GOIÂNIA | I4: GO | J4: 16 | K4: 7520951 | L4: 03P7520951 | M4: R2 | N4: =IF(_Shipments[[#This Row],[Embalagem]]="Big Bag",_Shipments[[#This Row],[Qtd.]]*_Shipments[[#This Row],[Qtde. sacos/palete]],_Shipments[[#This Row],[Qtd.]]) -> 16 | O4: =_xlfn.XLOOKUP(_Shipments[[#This Row],[CLN]],[2]Dados!$D:$D,[2]Dados!$R:$R,"-") -> 60 | P4: {=_xlfn.LET(_xlpm.t,_xlfn.XLOOKUP(_Shipments[[#This Row],[CLN]],[2]Dados!$D:$D,[2]Dados!$Q:$Q,"-"),_xlfn.IFS(LEFT(_xlpm.t,3)="PAS","Saco",LEFT(_xlpm.t,3)="PBT","Big Bag",TRUE,"-"))} -> Saco | Q4: =_xlfn.LET(_xlpm.p,_xlfn.XLOOKUP(_Shipments[[#This Row],[CLN]],[2]Dados!$D:$D,[2]Dados!$K:$K,"-"),_xlpm.n,_Shipments[[#This Row],[Qtde. sacos/palete]],IF(ISNUMBER(_xlpm.p),IF(_Shipments[[#This Row],[Embalagem]]="Big Bag",IF(ISNUMBER(_xlpm.n),_xlpm.p*_xlpm.n,"-"),_xlpm.p),"-")) -> 16.69 | R4: =IF(_Shipments[[#This Row],[Embalagem]]="Big Bag",_Shipments[[#This Row],[Qtd.]],ROUNDUP(_Shipments[[#This Row],[Qtd.]]/_Shipments[[#This Row],[Qtde. sacos/palete]],0)) -> 1 | S4: ECIO CRISTINO FERREIRA | T4: 34992119997 | U4: QDC-5910 | V4: HJC-1938 | W4: G10 TRANSPORTES S.A | Y4: 7240105
A5: =_xlfn.XLOOKUP(_Shipments[[#This Row],[Shipment]],[1]Report!$G:$G,[1]Report!$B:$B,"-") -> 46260.333 | B5: 7240103 | C5: 5541981925 | D5: 4 | E5: P3845VYHR-B821 | F5: 27 | G5: CORTEVA AGRISCIENCE DO BRASIL LTDA. | H5: APARECIDA DE GOIÂNIA | I5: GO | J5: 27 | K5: 7520927 | L5: 03P7520927 | M5: C2 | N5: =IF(_Shipments[[#This Row],[Embalagem]]="Big Bag",_Shipments[[#This Row],[Qtd.]]*_Shipments[[#This Row],[Qtde. sacos/palete]],_Shipments[[#This Row],[Qtd.]]) -> 27 | O5: =_xlfn.XLOOKUP(_Shipments[[#This Row],[CLN]],[2]Dados!$D:$D,[2]Dados!$R:$R,"-") -> 60 | P5: {=_xlfn.LET(_xlpm.t,_xlfn.XLOOKUP(_Shipments[[#This Row],[CLN]],[2]Dados!$D:$D,[2]Dados!$Q:$Q,"-"),_xlfn.IFS(LEFT(_xlpm.t,3)="PAS","Saco",LEFT(_xlpm.t,3)="PBT","Big Bag",TRUE,"-"))} -> Saco | Q5: =_xlfn.LET(_xlpm.p,_xlfn.XLOOKUP(_Shipments[[#This Row],[CLN]],[2]Dados!$D:$D,[2]Dados!$K:$K,"-"),_xlpm.n,_Shipments[[#This Row],[Qtde. sacos/palete]],IF(ISNUMBER(_xlpm.p),IF(_Shipments[[#This Row],[Embalagem]]="Big Bag",IF(ISNUMBER(_xlpm.n),_xlpm.p*_xlpm.n,"-"),_xlpm.p),"-")) -> 14.69 | R5: =IF(_Shipments[[#This Row],[Embalagem]]="Big Bag",_Shipments[[#This Row],[Qtd.]],ROUNDUP(_Shipments[[#This Row],[Qtd.]]/_Shipments[[#This Row],[Qtde. sacos/palete]],0)) -> 1 | S5: ECIO CRISTINO FERREIRA | T5: 34992119997 | U5: QDC-5910 | V5: HJC-1938 | W5: G10 TRANSPORTES S.A | Y5: 7240106
A6: =_xlfn.XLOOKUP(_Shipments[[#This Row],[Shipment]],[1]Report!$G:$G,[1]Report!$B:$B,"-") -> 46260.333 | B6: 7240103 | C6: 5541981925 | D6: 5 | E6: P3845VYHR-B821 | F6: 31 | G6: CORTEVA AGRISCIENCE DO BRASIL LTDA. | H6: APARECIDA DE GOIÂNIA | I6: GO | J6: 31 | K6: 7520929 | L6: 03P7520929 | M6: C2 | N6: =IF(_Shipments[[#This Row],[Embalagem]]="Big Bag",_Shipments[[#This Row],[Qtd.]]*_Shipments[[#This Row],[Qtde. sacos/palete]],_Shipments[[#This Row],[Qtd.]]) -> 31 | O6: =_xlfn.XLOOKUP(_Shipments[[#This Row],[CLN]],[2]Dados!$D:$D,[2]Dados!$R:$R,"-") -> 70 | P6: {=_xlfn.LET(_xlpm.t,_xlfn.XLOOKUP(_Shipments[[#This Row],[CLN]],[2]Dados!$D:$D,[2]Dados!$Q:$Q,"-"),_xlfn.IFS(LEFT(_xlpm.t,3)="PAS","Saco",LEFT(_xlpm.t,3)="PBT","Big Bag",TRUE,"-"))} -> Saco | Q6: =_xlfn.LET(_xlpm.p,_xlfn.XLOOKUP(_Shipments[[#This Row],[CLN]],[2]Dados!$D:$D,[2]Dados!$K:$K,"-"),_xlpm.n,_Shipments[[#This Row],[Qtde. sacos/palete]],IF(ISNUMBER(_xlpm.p),IF(_Shipments[[#This Row],[Embalagem]]="Big Bag",IF(ISNUMBER(_xlpm.n),_xlpm.p*_xlpm.n,"-"),_xlpm.p),"-")) -> 14.13 | R6: =IF(_Shipments[[#This Row],[Embalagem]]="Big Bag",_Shipments[[#This Row],[Qtd.]],ROUNDUP(_Shipments[[#This Row],[Qtd.]]/_Shipments[[#This Row],[Qtde. sacos/palete]],0)) -> 1 | S6: ECIO CRISTINO FERREIRA | T6: 34992119997 | U6: QDC-5910 | V6: HJC-1938 | W6: G10 TRANSPORTES S.A | Y6: 7240107
A7: =_xlfn.XLOOKUP(_Shipments[[#This Row],[Shipment]],[1]Report!$G:$G,[1]Report!$B:$B,"-") -> 46260.333 | B7: 7240103 | C7: 5541981925 | D7: 6 | E7: P3845VYHR-B822 | F7: 195 | G7: CORTEVA AGRISCIENCE DO BRASIL LTDA. | H7: APARECIDA DE GOIÂNIA | I7: GO | J7: 195 | K7: 7520886 | L7: 03P7520886 | M7: C3C | N7: =IF(_Shipments[[#This Row],[Embalagem]]="Big Bag",_Shipments[[#This Row],[Qtd.]]*_Shipments[[#This Row],[Qtde. sacos/palete]],_Shipments[[#This Row],[Qtd.]]) -> 195 | O7: =_xlfn.XLOOKUP(_Shipments[[#This Row],[CLN]],[2]Dados!$D:$D,[2]Dados!$R:$R,"-") -> 75 | P7: {=_xlfn.LET(_xlpm.t,_xlfn.XLOOKUP(_Shipments[[#This Row],[CLN]],[2]Dados!$D:$D,[2]Dados!$Q:$Q,"-"),_xlfn.IFS(LEFT(_xlpm.t,3)="PAS","Saco",LEFT(_xlpm.t,3)="PBT","Big Bag",TRUE,"-"))} -> Saco | Q7: =_xlfn.LET(_xlpm.p,_xlfn.XLOOKUP(_Shipments[[#This Row],[CLN]],[2]Dados!$D:$D,[2]Dados!$K:$K,"-"),_xlpm.n,_Shipments[[#This Row],[Qtde. sacos/palete]],IF(ISNUMBER(_xlpm.p),IF(_Shipments[[#This Row],[Embalagem]]="Big Bag",IF(ISNUMBER(_xlpm.n),_xlpm.p*_xlpm.n,"-"),_xlpm.p),"-")) -> 11.26 | R7: =IF(_Shipments[[#This Row],[Embalagem]]="Big Bag",_Shipments[[#This Row],[Qtd.]],ROUNDUP(_Shipments[[#This Row],[Qtd.]]/_Shipments[[#This Row],[Qtde. sacos/palete]],0)) -> 3 | S7: ECIO CRISTINO FERREIRA | T7: 34992119997 | U7: QDC-5910 | V7: HJC-1938 | W7: G10 TRANSPORTES S.A | Y7: 7240108
A8: =_xlfn.XLOOKUP(_Shipments[[#This Row],[Shipment]],[1]Report!$G:$G,[1]Report!$B:$B,"-") -> 46260.333 | B8: 7240104 | C8: 5541981926 | D8: 1 | E8: P3845VYHR-B825 | F8: 925 | G8: CORTEVA AGRISCIENCE DO BRASIL LTDA. | H8: APARECIDA DE GOIÂNIA | I8: GO | J8: 925 | K8: 7520891 | L8: 03P7520891 | M8: R3C | N8: =IF(_Shipments[[#This Row],[Embalagem]]="Big Bag",_Shipments[[#This Row],[Qtd.]]*_Shipments[[#This Row],[Qtde. sacos/palete]],_Shipments[[#This Row],[Qtd.]]) -> 925 | O8: =_xlfn.XLOOKUP(_Shipments[[#This Row],[CLN]],[2]Dados!$D:$D,[2]Dados!$R:$R,"-") -> 70 | P8: {=_xlfn.LET(_xlpm.t,_xlfn.XLOOKUP(_Shipments[[#This Row],[CLN]],[2]Dados!$D:$D,[2]Dados!$Q:$Q,"-"),_xlfn.IFS(LEFT(_xlpm.t,3)="PAS","Saco",LEFT(_xlpm.t,3)="PBT","Big Bag",TRUE,"-"))} -> Saco | Q8: =_xlfn.LET(_xlpm.p,_xlfn.XLOOKUP(_Shipments[[#This Row],[CLN]],[2]Dados!$D:$D,[2]Dados!$K:$K,"-"),_xlpm.n,_Shipments[[#This Row],[Qtde. sacos/palete]],IF(ISNUMBER(_xlpm.p),IF(_Shipments[[#This Row],[Embalagem]]="Big Bag",IF(ISNUMBER(_xlpm.n),_xlpm.p*_xlpm.n,"-"),_xlpm.p),"-")) -> 13.11 | R8: =IF(_Shipments[[#This Row],[Embalagem]]="Big Bag",_Shipments[[#This Row],[Qtd.]],ROUNDUP(_Shipments[[#This Row],[Qtd.]]/_Shipments[[#This Row],[Qtde. sacos/palete]],0)) -> 14 | S8: MARCILIO NUNES GOMES | T8: 38999337997 | U8: FHS-8D82 | V8: SJG-2J59 | W8: G10 TRANSPORTES S.A | Y8: 7240109
A9: =_xlfn.XLOOKUP(_Shipments[[#This Row],[Shipment]],[1]Report!$G:$G,[1]Report!$B:$B,"-") -> 46260.333 | B9: 7240104 | C9: 5541981926 | D9: 2 | E9: P3845VYHR-B821 | F9: 39 | G9: CORTEVA AGRISCIENCE DO BRASIL LTDA. | H9: APARECIDA DE GOIÂNIA | I9: GO | J9: 39 | K9: 7520933 | L9: 03P7520933 | M9: C2 | N9: =IF(_Shipments[[#This Row],[Embalagem]]="Big Bag",_Shipments[[#This Row],[Qtd.]]*_Shipments[[#This Row],[Qtde. sacos/palete]],_Shipments[[#This Row],[Qtd.]]) -> 39 | O9: =_xlfn.XLOOKUP(_Shipments[[#This Row],[CLN]],[2]Dados!$D:$D,[2]Dados!$R:$R,"-") -> 60 | P9: {=_xlfn.LET(_xlpm.t,_xlfn.XLOOKUP(_Shipments[[#This Row],[CLN]],[2]Dados!$D:$D,[2]Dados!$Q:$Q,"-"),_xlfn.IFS(LEFT(_xlpm.t,3)="PAS","Saco",LEFT(_xlpm.t,3)="PBT","Big Bag",TRUE,"-"))} -> Saco | Q9: =_xlfn.LET(_xlpm.p,_xlfn.XLOOKUP(_Shipments[[#This Row],[CLN]],[2]Dados!$D:$D,[2]Dados!$K:$K,"-"),_xlpm.n,_Shipments[[#This Row],[Qtde. sacos/palete]],IF(ISNUMBER(_xlpm.p),IF(_Shipments[[#This Row],[Embalagem]]="Big Bag",IF(ISNUMBER(_xlpm.n),_xlpm.p*_xlpm.n,"-"),_xlpm.p),"-")) -> 14.56 | R9: =IF(_Shipments[[#This Row],[Embalagem]]="Big Bag",_Shipments[[#This Row],[Qtd.]],ROUNDUP(_Shipments[[#This Row],[Qtd.]]/_Shipments[[#This Row],[Qtde. sacos/palete]],0)) -> 1 | S9: MARCILIO NUNES GOMES | T9: 38999337997 | U9: FHS-8D82 | V9: SJG-2J59 | W9: G10 TRANSPORTES S.A | Y9: 7240110
A10: =_xlfn.XLOOKUP(_Shipments[[#This Row],[Shipment]],[1]Report!$G:$G,[1]Report!$B:$B,"-") -> 46260.333 | B10: 7240104 | C10: 5541981926 | D10: 3 | E10: P3845VYHR-B821 | F10: 27 | G10: CORTEVA AGRISCIENCE DO BRASIL LTDA. | H10: APARECIDA DE GOIÂNIA | I10: GO | J10: 27 | K10: 7520936 | L10: 03P7520936 | M10: C1 | N10: =IF(_Shipments[[#This Row],[Embalagem]]="Big Bag",_Shipments[[#This Row],[Qtd.]]*_Shipments[[#This Row],[Qtde. sacos/palete]],_Shipments[[#This Row],[Qtd.]]) -> 27 | O10: =_xlfn.XLOOKUP(_Shipments[[#This Row],[CLN]],[2]Dados!$D:$D,[2]Dados!$R:$R,"-") -> 60 | P10: {=_xlfn.LET(_xlpm.t,_xlfn.XLOOKUP(_Shipments[[#This Row],[CLN]],[2]Dados!$D:$D,[2]Dados!$Q:$Q,"-"),_xlfn.IFS(LEFT(_xlpm.t,3)="PAS","Saco",LEFT(_xlpm.t,3)="PBT","Big Bag",TRUE,"-"))} -> Saco | Q10: =_xlfn.LET(_xlpm.p,_xlfn.XLOOKUP(_Shipments[[#This Row],[CLN]],[2]Dados!$D:$D,[2]Dados!$K:$K,"-"),_xlpm.n,_Shipments[[#This Row],[Qtde. sacos/palete]],IF(ISNUMBER(_xlpm.p),IF(_Shipments[[#This Row],[Embalagem]]="Big Bag",IF(ISNUMBER(_xlpm.n),_xlpm.p*_xlpm.n,"-"),_xlpm.p),"-")) -> 16.18 | R10: =IF(_Shipments[[#This Row],[Embalagem]]="Big Bag",_Shipments[[#This Row],[Qtd.]],ROUNDUP(_Shipments[[#This Row],[Qtd.]]/_Shipments[[#This Row],[Qtde. sacos/palete]],0)) -> 1 | S10: MARCILIO NUNES GOMES | T10: 38999337997 | U10: FHS-8D82 | V10: SJG-2J59 | W10: G10 TRANSPORTES S.A | Y10: 7240111
A11: =_xlfn.XLOOKUP(_Shipments[[#This Row],[Shipment]],[1]Report!$G:$G,[1]Report!$B:$B,"-") -> 46260.333 | B11: 7240104 | C11: 5541981926 | D11: 4 | E11: P3845VYHR-B821 | F11: 39 | G11: CORTEVA AGRISCIENCE DO BRASIL LTDA. | H11: APARECIDA DE GOIÂNIA | I11: GO | J11: 39 | K11: 7520939 | L11: 03P7520939 | M11: C1 | N11: =IF(_Shipments[[#This Row],[Embalagem]]="Big Bag",_Shipments[[#This Row],[Qtd.]]*_Shipments[[#This Row],[Qtde. sacos/palete]],_Shipments[[#This Row],[Qtd.]]) -> 39 | O11: =_xlfn.XLOOKUP(_Shipments[[#This Row],[CLN]],[2]Dados!$D:$D,[2]Dados!$R:$R,"-") -> 60 | P11: {=_xlfn.LET(_xlpm.t,_xlfn.XLOOKUP(_Shipments[[#This Row],[CLN]],[2]Dados!$D:$D,[2]Dados!$Q:$Q,"-"),_xlfn.IFS(LEFT(_xlpm.t,3)="PAS","Saco",LEFT(_xlpm.t,3)="PBT","Big Bag",TRUE,"-"))} -> Saco | Q11: =_xlfn.LET(_xlpm.p,_xlfn.XLOOKUP(_Shipments[[#This Row],[CLN]],[2]Dados!$D:$D,[2]Dados!$K:$K,"-"),_xlpm.n,_Shipments[[#This Row],[Qtde. sacos/palete]],IF(ISNUMBER(_xlpm.p),IF(_Shipments[[#This Row],[Embalagem]]="Big Bag",IF(ISNUMBER(_xlpm.n),_xlpm.p*_xlpm.n,"-"),_xlpm.p),"-")) -> 16.84 | R11: =IF(_Shipments[[#This Row],[Embalagem]]="Big Bag",_Shipments[[#This Row],[Qtd.]],ROUNDUP(_Shipments[[#This Row],[Qtd.]]/_Shipments[[#This Row],[Qtde. sacos/palete]],0)) -> 1 | S11: MARCILIO NUNES GOMES | T11: 38999337997 | U11: FHS-8D82 | V11: SJG-2J59 | W11: G10 TRANSPORTES S.A | Y11: 7241110
A12: =_xlfn.XLOOKUP(_Shipments[[#This Row],[Shipment]],[1]Report!$G:$G,[1]Report!$B:$B,"-") -> 46260.333 | B12: 7240104 | C12: 5541981926 | D12: 5 | E12: P3845VYHR-B825 | F12: 37 | G12: CORTEVA AGRISCIENCE DO BRASIL LTDA. | H12: APARECIDA DE GOIÂNIA | I12: GO | J12: 37 | K12: 7520948 | L12: 03P7520948 | M12: R3 | N12: =IF(_Shipments[[#This Row],[Embalagem]]="Big Bag",_Shipments[[#This Row],[Qtd.]]*_Shipments[[#This Row],[Qtde. sacos/palete]],_Shipments[[#This Row],[Qtd.]]) -> 37 | O12: =_xlfn.XLOOKUP(_Shipments[[#This Row],[CLN]],[2]Dados!$D:$D,[2]Dados!$R:$R,"-") -> 70 | P12: {=_xlfn.LET(_xlpm.t,_xlfn.XLOOKUP(_Shipments[[#This Row],[CLN]],[2]Dados!$D:$D,[2]Dados!$Q:$Q,"-"),_xlfn.IFS(LEFT(_xlpm.t,3)="PAS","Saco",LEFT(_xlpm.t,3)="PBT","Big Bag",TRUE,"-"))} -> Saco | Q12: =_xlfn.LET(_xlpm.p,_xlfn.XLOOKUP(_Shipments[[#This Row],[CLN]],[2]Dados!$D:$D,[2]Dados!$K:$K,"-"),_xlpm.n,_Shipments[[#This Row],[Qtde. sacos/palete]],IF(ISNUMBER(_xlpm.p),IF(_Shipments[[#This Row],[Embalagem]]="Big Bag",IF(ISNUMBER(_xlpm.n),_xlpm.p*_xlpm.n,"-"),_xlpm.p),"-")) -> 14.06 | R12: =IF(_Shipments[[#This Row],[Embalagem]]="Big Bag",_Shipments[[#This Row],[Qtd.]],ROUNDUP(_Shipments[[#This Row],[Qtd.]]/_Shipments[[#This Row],[Qtde. sacos/palete]],0)) -> 1 | S12: MARCILIO NUNES GOMES | T12: 38999337997 | U12: FHS-8D82 | V12: SJG-2J59 | W12: G10 TRANSPORTES S.A | Y12: 7241111
A13: =_xlfn.XLOOKUP(_Shipments[[#This Row],[Shipment]],[1]Report!$G:$G,[1]Report!$B:$B,"-") -> 46260.333 | B13: 7240104 | C13: 5541981926 | D13: 6 | E13: P3845VYHR-B822 | F13: 207 | G13: CORTEVA AGRISCIENCE DO BRASIL LTDA. | H13: APARECIDA DE GOIÂNIA | I13: GO | J13: 207 | K13: 7520924 | L13: 03P7520924 | M13: C3 | N13: =IF(_Shipments[[#This Row],[Embalagem]]="Big Bag",_Shipments[[#This Row],[Qtd.]]*_Shipments[[#This Row],[Qtde. sacos/palete]],_Shipments[[#This Row],[Qtd.]]) -> 207 | O13: =_xlfn.XLOOKUP(_Shipments[[#This Row],[CLN]],[2]Dados!$D:$D,[2]Dados!$R:$R,"-") -> 70 | P13: {=_xlfn.LET(_xlpm.t,_xlfn.XLOOKUP(_Shipments[[#This Row],[CLN]],[2]Dados!$D:$D,[2]Dados!$Q:$Q,"-"),_xlfn.IFS(LEFT(_xlpm.t,3)="PAS","Saco",LEFT(_xlpm.t,3)="PBT","Big Bag",TRUE,"-"))} -> Saco | Q13: =_xlfn.LET(_xlpm.p,_xlfn.XLOOKUP(_Shipments[[#This Row],[CLN]],[2]Dados!$D:$D,[2]Dados!$K:$K,"-"),_xlpm.n,_Shipments[[#This Row],[Qtde. sacos/palete]],IF(ISNUMBER(_xlpm.p),IF(_Shipments[[#This Row],[Embalagem]]="Big Bag",IF(ISNUMBER(_xlpm.n),_xlpm.p*_xlpm.n,"-"),_xlpm.p),"-")) -> 13.26 | R13: =IF(_Shipments[[#This Row],[Embalagem]]="Big Bag",_Shipments[[#This Row],[Qtd.]],ROUNDUP(_Shipments[[#This Row],[Qtd.]]/_Shipments[[#This Row],[Qtde. sacos/palete]],0)) -> 3 | S13: MARCILIO NUNES GOMES | T13: 38999337997 | U13: FHS-8D82 | V13: SJG-2J59 | W13: G10 TRANSPORTES S.A | Y13: 7241113
... A76: =_xlfn.XLOOKUP(_Shipments[[#This Row],[Shipment]],[1]Report!$G:$G,[1]Report!$B:$B,"-") -> 46275.333 | B76: 7241954 | C76: 5541984145 | D76: 16 | E76: P3845VYHR-B825 | F76: 13 | G76: CORTEVA AGRISCIENCE DO BRASIL LTDA. | H76: UBERLÂNDIA | I76: MG | J76: 13 | K76: 7566291 | L76: 03P7566291 | M76: R3 | N76: =IF(_Shipments[[#This Row],[Embalagem]]="Big Bag",_Shipments[[#This Row],[Qtd.]]*_Shipments[[#This Row],[Qtde. sacos/palete]],_Shipments[[#This Row],[Qtd.]]) -> 13 | O76: =_xlfn.XLOOKUP(_Shipments[[#This Row],[CLN]],[2]Dados!$D:$D,[2]Dados!$R:$R,"-") -> 60 | P76: {=_xlfn.LET(_xlpm.t,_xlfn.XLOOKUP(_Shipments[[#This Row],[CLN]],[2]Dados!$D:$D,[2]Dados!$Q:$Q,"-"),_xlfn.IFS(LEFT(_xlpm.t,3)="PAS","Saco",LEFT(_xlpm.t,3)="PBT","Big Bag",TRUE,"-"))} -> Saco | Q76: =_xlfn.LET(_xlpm.p,_xlfn.XLOOKUP(_Shipments[[#This Row],[CLN]],[2]Dados!$D:$D,[2]Dados!$K:$K,"-"),_xlpm.n,_Shipments[[#This Row],[Qtde. sacos/palete]],IF(ISNUMBER(_xlpm.p),IF(_Shipments[[#This Row],[Embalagem]]="Big Bag",IF(ISNUMBER(_xlpm.n),_xlpm.p*_xlpm.n,"-"),_xlpm.p),"-")) -> 16.67 | R76: =IF(_Shipments[[#This Row],[Embalagem]]="Big Bag",_Shipments[[#This Row],[Qtd.]],ROUNDUP(_Shipments[[#This Row],[Qtd.]]/_Shipments[[#This Row],[Qtde. sacos/palete]],0)) -> 1 | S76: JULIO CESAR DE OLIVEIRA | T76: 34999248710 | U76: AZN-6580 | V76: ORA-1733 | W76: G10 TRANSPORTES S.A | Y76: 7244343
A77: =_xlfn.XLOOKUP(_Shipments[[#This Row],[Shipment]],[1]Report!$G:$G,[1]Report!$B:$B,"-") -> 46275.333 | B77: 7241954 | C77: 5541984145 | D77: 17 | E77: P3845VYHR-B821 | F77: 22 | G77: CORTEVA AGRISCIENCE DO BRASIL LTDA. | H77: UBERLÂNDIA | I77: MG | J77: 22 | K77: 7566301 | L77: 03P7566301 | M77: C2 | N77: =IF(_Shipments[[#This Row],[Embalagem]]="Big Bag",_Shipments[[#This Row],[Qtd.]]*_Shipments[[#This Row],[Qtde. sacos/palete]],_Shipments[[#This Row],[Qtd.]]) -> 22 | O77: =_xlfn.XLOOKUP(_Shipments[[#This Row],[CLN]],[2]Dados!$D:$D,[2]Dados!$R:$R,"-") -> 60 | P77: {=_xlfn.LET(_xlpm.t,_xlfn.XLOOKUP(_Shipments[[#This Row],[CLN]],[2]Dados!$D:$D,[2]Dados!$Q:$Q,"-"),_xlfn.IFS(LEFT(_xlpm.t,3)="PAS","Saco",LEFT(_xlpm.t,3)="PBT","Big Bag",TRUE,"-"))} -> Saco | Q77: =_xlfn.LET(_xlpm.p,_xlfn.XLOOKUP(_Shipments[[#This Row],[CLN]],[2]Dados!$D:$D,[2]Dados!$K:$K,"-"),_xlpm.n,_Shipments[[#This Row],[Qtde. sacos/palete]],IF(ISNUMBER(_xlpm.p),IF(_Shipments[[#This Row],[Embalagem]]="Big Bag",IF(ISNUMBER(_xlpm.n),_xlpm.p*_xlpm.n,"-"),_xlpm.p),"-")) -> 17.47 | R77: =IF(_Shipments[[#This Row],[Embalagem]]="Big Bag",_Shipments[[#This Row],[Qtd.]],ROUNDUP(_Shipments[[#This Row],[Qtd.]]/_Shipments[[#This Row],[Qtde. sacos/palete]],0)) -> 1 | S77: JULIO CESAR DE OLIVEIRA | T77: 34999248710 | U77: AZN-6580 | V77: ORA-1733 | W77: G10 TRANSPORTES S.A
A78: =_xlfn.XLOOKUP(_Shipments[[#This Row],[Shipment]],[1]Report!$G:$G,[1]Report!$B:$B,"-") -> 46275.333 | B78: 7241954 | C78: 5541984145 | D78: 18 | E78: P3845VYHR-B821 | F78: 24 | G78: CORTEVA AGRISCIENCE DO BRASIL LTDA. | H78: UBERLÂNDIA | I78: MG | J78: 24 | K78: 7566302 | L78: 03P7566302 | M78: C2 | N78: =IF(_Shipments[[#This Row],[Embalagem]]="Big Bag",_Shipments[[#This Row],[Qtd.]]*_Shipments[[#This Row],[Qtde. sacos/palete]],_Shipments[[#This Row],[Qtd.]]) -> 24 | O78: =_xlfn.XLOOKUP(_Shipments[[#This Row],[CLN]],[2]Dados!$D:$D,[2]Dados!$R:$R,"-") -> 50 | P78: {=_xlfn.LET(_xlpm.t,_xlfn.XLOOKUP(_Shipments[[#This Row],[CLN]],[2]Dados!$D:$D,[2]Dados!$Q:$Q,"-"),_xlfn.IFS(LEFT(_xlpm.t,3)="PAS","Saco",LEFT(_xlpm.t,3)="PBT","Big Bag",TRUE,"-"))} -> Saco | Q78: =_xlfn.LET(_xlpm.p,_xlfn.XLOOKUP(_Shipments[[#This Row],[CLN]],[2]Dados!$D:$D,[2]Dados!$K:$K,"-"),_xlpm.n,_Shipments[[#This Row],[Qtde. sacos/palete]],IF(ISNUMBER(_xlpm.p),IF(_Shipments[[#This Row],[Embalagem]]="Big Bag",IF(ISNUMBER(_xlpm.n),_xlpm.p*_xlpm.n,"-"),_xlpm.p),"-")) -> 17.6 | R78: =IF(_Shipments[[#This Row],[Embalagem]]="Big Bag",_Shipments[[#This Row],[Qtd.]],ROUNDUP(_Shipments[[#This Row],[Qtd.]]/_Shipments[[#This Row],[Qtde. sacos/palete]],0)) -> 1 | S78: JULIO CESAR DE OLIVEIRA | T78: 34999248710 | U78: AZN-6580 | V78: ORA-1733 | W78: G10 TRANSPORTES S.A
A79: =_xlfn.XLOOKUP(_Shipments[[#This Row],[Shipment]],[1]Report!$G:$G,[1]Report!$B:$B,"-") -> 46275.333 | B79: 7241954 | C79: 5541984145 | D79: 19 | E79: P3845VYHR-B821 | F79: 28 | G79: CORTEVA AGRISCIENCE DO BRASIL LTDA. | H79: UBERLÂNDIA | I79: MG | J79: 28 | K79: 7520935 | L79: 03P7520935 | M79: C1 | N79: =IF(_Shipments[[#This Row],[Embalagem]]="Big Bag",_Shipments[[#This Row],[Qtd.]]*_Shipments[[#This Row],[Qtde. sacos/palete]],_Shipments[[#This Row],[Qtd.]]) -> 28 | O79: =_xlfn.XLOOKUP(_Shipments[[#This Row],[CLN]],[2]Dados!$D:$D,[2]Dados!$R:$R,"-") -> 60 | P79: {=_xlfn.LET(_xlpm.t,_xlfn.XLOOKUP(_Shipments[[#This Row],[CLN]],[2]Dados!$D:$D,[2]Dados!$Q:$Q,"-"),_xlfn.IFS(LEFT(_xlpm.t,3)="PAS","Saco",LEFT(_xlpm.t,3)="PBT","Big Bag",TRUE,"-"))} -> Saco | Q79: =_xlfn.LET(_xlpm.p,_xlfn.XLOOKUP(_Shipments[[#This Row],[CLN]],[2]Dados!$D:$D,[2]Dados!$K:$K,"-"),_xlpm.n,_Shipments[[#This Row],[Qtde. sacos/palete]],IF(ISNUMBER(_xlpm.p),IF(_Shipments[[#This Row],[Embalagem]]="Big Bag",IF(ISNUMBER(_xlpm.n),_xlpm.p*_xlpm.n,"-"),_xlpm.p),"-")) -> 16.91 | R79: =IF(_Shipments[[#This Row],[Embalagem]]="Big Bag",_Shipments[[#This Row],[Qtd.]],ROUNDUP(_Shipments[[#This Row],[Qtd.]]/_Shipments[[#This Row],[Qtde. sacos/palete]],0)) -> 1 | S79: JULIO CESAR DE OLIVEIRA | T79: 34999248710 | U79: AZN-6580 | V79: ORA-1733 | W79: G10 TRANSPORTES S.A
A80: =_xlfn.XLOOKUP(_Shipments[[#This Row],[Shipment]],[1]Report!$G:$G,[1]Report!$B:$B,"-") -> 46275.333 | B80: 7241954 | C80: 5541984145 | D80: 20 | E80: P3845VYHR-B821 | F80: 33 | G80: CORTEVA AGRISCIENCE DO BRASIL LTDA. | H80: UBERLÂNDIA | I80: MG | J80: 33 | K80: 7550836 | L80: 03P7550836 | M80: C2 | N80: =IF(_Shipments[[#This Row],[Embalagem]]="Big Bag",_Shipments[[#This Row],[Qtd.]]*_Shipments[[#This Row],[Qtde. sacos/palete]],_Shipments[[#This Row],[Qtd.]]) -> 33 | O80: =_xlfn.XLOOKUP(_Shipments[[#This Row],[CLN]],[2]Dados!$D:$D,[2]Dados!$R:$R,"-") -> 60 | P80: {=_xlfn.LET(_xlpm.t,_xlfn.XLOOKUP(_Shipments[[#This Row],[CLN]],[2]Dados!$D:$D,[2]Dados!$Q:$Q,"-"),_xlfn.IFS(LEFT(_xlpm.t,3)="PAS","Saco",LEFT(_xlpm.t,3)="PBT","Big Bag",TRUE,"-"))} -> Saco | Q80: =_xlfn.LET(_xlpm.p,_xlfn.XLOOKUP(_Shipments[[#This Row],[CLN]],[2]Dados!$D:$D,[2]Dados!$K:$K,"-"),_xlpm.n,_Shipments[[#This Row],[Qtde. sacos/palete]],IF(ISNUMBER(_xlpm.p),IF(_Shipments[[#This Row],[Embalagem]]="Big Bag",IF(ISNUMBER(_xlpm.n),_xlpm.p*_xlpm.n,"-"),_xlpm.p),"-")) -> 14.89 | R80: =IF(_Shipments[[#This Row],[Embalagem]]="Big Bag",_Shipments[[#This Row],[Qtd.]],ROUNDUP(_Shipments[[#This Row],[Qtd.]]/_Shipments[[#This Row],[Qtde. sacos/palete]],0)) -> 1 | S80: JULIO CESAR DE OLIVEIRA | T80: 34999248710 | U80: AZN-6580 | V80: ORA-1733 | W80: G10 TRANSPORTES S.A
A81: =_xlfn.XLOOKUP(_Shipments[[#This Row],[Shipment]],[1]Report!$G:$G,[1]Report!$B:$B,"-") -> 46275.333 | B81: 7241954 | C81: 5541984145 | D81: 21 | E81: P3845VYHR-B824 | F81: 22 | G81: CORTEVA AGRISCIENCE DO BRASIL LTDA. | H81: UBERLÂNDIA | I81: MG | J81: 22 | K81: 7520962 | L81: 03P7520962 | M81: R1 | N81: =IF(_Shipments[[#This Row],[Embalagem]]="Big Bag",_Shipments[[#This Row],[Qtd.]]*_Shipments[[#This Row],[Qtde. sacos/palete]],_Shipments[[#This Row],[Qtd.]]) -> 22 | O81: =_xlfn.XLOOKUP(_Shipments[[#This Row],[CLN]],[2]Dados!$D:$D,[2]Dados!$R:$R,"-") -> 45 | P81: {=_xlfn.LET(_xlpm.t,_xlfn.XLOOKUP(_Shipments[[#This Row],[CLN]],[2]Dados!$D:$D,[2]Dados!$Q:$Q,"-"),_xlfn.IFS(LEFT(_xlpm.t,3)="PAS","Saco",LEFT(_xlpm.t,3)="PBT","Big Bag",TRUE,"-"))} -> Saco | Q81: =_xlfn.LET(_xlpm.p,_xlfn.XLOOKUP(_Shipments[[#This Row],[CLN]],[2]Dados!$D:$D,[2]Dados!$K:$K,"-"),_xlpm.n,_Shipments[[#This Row],[Qtde. sacos/palete]],IF(ISNUMBER(_xlpm.p),IF(_Shipments[[#This Row],[Embalagem]]="Big Bag",IF(ISNUMBER(_xlpm.n),_xlpm.p*_xlpm.n,"-"),_xlpm.p),"-")) -> 22.38 | R81: =IF(_Shipments[[#This Row],[Embalagem]]="Big Bag",_Shipments[[#This Row],[Qtd.]],ROUNDUP(_Shipments[[#This Row],[Qtd.]]/_Shipments[[#This Row],[Qtde. sacos/palete]],0)) -> 1 | S81: JULIO CESAR DE OLIVEIRA | T81: 34999248710 | U81: AZN-6580 | V81: ORA-1733 | W81: G10 TRANSPORTES S.A
A82: =_xlfn.XLOOKUP(_Shipments[[#This Row],[Shipment]],[1]Report!$G:$G,[1]Report!$B:$B,"-") -> 46268.333 | B82: 7241962 | C82: 5541984151 | D82: 1 | E82: P3845VYHR-B844 | F82: 18 | G82: CORTEVA AGRISCIENCE DO BRASIL LTDA. | H82: APARECIDA DE GOIÂNIA | I82: GO | J82: 18 | K82: 7518210 | L82: 03P7518210 | M82: R2 | N82: =IF(_Shipments[[#This Row],[Embalagem]]="Big Bag",_Shipments[[#This Row],[Qtd.]]*_Shipments[[#This Row],[Qtde. sacos/palete]],_Shipments[[#This Row],[Qtd.]]) -> 720 | O82: =_xlfn.XLOOKUP(_Shipments[[#This Row],[CLN]],[2]Dados!$D:$D,[2]Dados!$R:$R,"-") -> 40 | P82: {=_xlfn.LET(_xlpm.t,_xlfn.XLOOKUP(_Shipments[[#This Row],[CLN]],[2]Dados!$D:$D,[2]Dados!$Q:$Q,"-"),_xlfn.IFS(LEFT(_xlpm.t,3)="PAS","Saco",LEFT(_xlpm.t,3)="PBT","Big Bag",TRUE,"-"))} -> Big Bag | Q82: =_xlfn.LET(_xlpm.p,_xlfn.XLOOKUP(_Shipments[[#This Row],[CLN]],[2]Dados!$D:$D,[2]Dados!$K:$K,"-"),_xlpm.n,_Shipments[[#This Row],[Qtde. sacos/palete]],IF(ISNUMBER(_xlpm.p),IF(_Shipments[[#This Row],[Embalagem]]="Big Bag",IF(ISNUMBER(_xlpm.n),_xlpm.p*_xlpm.n,"-"),_xlpm.p),"-")) -> 667.6 | R82: =IF(_Shipments[[#This Row],[Embalagem]]="Big Bag",_Shipments[[#This Row],[Qtd.]],ROUNDUP(_Shipments[[#This Row],[Qtd.]]/_Shipments[[#This Row],[Qtde. sacos/palete]],0)) -> 18 | S82: DENILSON LAZARO CORREA | T82: 34999031784 | U82: NSI-5E04 | V82: SCU-6D73 | W82: G10 TRANSPORTES S.A
A83: =_xlfn.XLOOKUP(_Shipments[[#This Row],[Shipment]],[1]Report!$G:$G,[1]Report!$B:$B,"-") -> 46268.333 | B83: 7241962 | C83: 5541984151 | D83: 2 | E83: P3845VYHR-B841 | F83: 3 | G83: CORTEVA AGRISCIENCE DO BRASIL LTDA. | H83: APARECIDA DE GOIÂNIA | I83: GO | J83: 3 | K83: 7518134 | L83: 03P7518134 | M83: C2 | N83: =IF(_Shipments[[#This Row],[Embalagem]]="Big Bag",_Shipments[[#This Row],[Qtd.]]*_Shipments[[#This Row],[Qtde. sacos/palete]],_Shipments[[#This Row],[Qtd.]]) -> 120 | O83: =_xlfn.XLOOKUP(_Shipments[[#This Row],[CLN]],[2]Dados!$D:$D,[2]Dados!$R:$R,"-") -> 40 | P83: {=_xlfn.LET(_xlpm.t,_xlfn.XLOOKUP(_Shipments[[#This Row],[CLN]],[2]Dados!$D:$D,[2]Dados!$Q:$Q,"-"),_xlfn.IFS(LEFT(_xlpm.t,3)="PAS","Saco",LEFT(_xlpm.t,3)="PBT","Big Bag",TRUE,"-"))} -> Big Bag | Q83: =_xlfn.LET(_xlpm.p,_xlfn.XLOOKUP(_Shipments[[#This Row],[CLN]],[2]Dados!$D:$D,[2]Dados!$K:$K,"-"),_xlpm.n,_Shipments[[#This Row],[Qtde. sacos/palete]],IF(ISNUMBER(_xlpm.p),IF(_Shipments[[#This Row],[Embalagem]]="Big Bag",IF(ISNUMBER(_xlpm.n),_xlpm.p*_xlpm.n,"-"),_xlpm.p),"-")) -> 591.6 | R83: =IF(_Shipments[[#This Row],[Embalagem]]="Big Bag",_Shipments[[#This Row],[Qtd.]],ROUNDUP(_Shipments[[#This Row],[Qtd.]]/_Shipments[[#This Row],[Qtde. sacos/palete]],0)) -> 3 | S83: DENILSON LAZARO CORREA | T83: 34999031784 | U83: NSI-5E04 | V83: SCU-6D73 | W83: G10 TRANSPORTES S.A
A84: =_xlfn.XLOOKUP(_Shipments[[#This Row],[Shipment]],[1]Report!$G:$G,[1]Report!$B:$B,"-") -> 46275.333 | B84: 7241989 | C84: 5541984189 | D84: 1 | E84: P3845VYHR-B841 | F84: 21 | G84: CORTEVA AGRISCIENCE DO BRASIL LTDA. | H84: UBERLÂNDIA | I84: MG | J84: 21 | K84: 7518145 | L84: 03P7518145 | M84: C1 | N84: =IF(_Shipments[[#This Row],[Embalagem]]="Big Bag",_Shipments[[#This Row],[Qtd.]]*_Shipments[[#This Row],[Qtde. sacos/palete]],_Shipments[[#This Row],[Qtd.]]) -> 840 | O84: =_xlfn.XLOOKUP(_Shipments[[#This Row],[CLN]],[2]Dados!$D:$D,[2]Dados!$R:$R,"-") -> 40 | P84: {=_xlfn.LET(_xlpm.t,_xlfn.XLOOKUP(_Shipments[[#This Row],[CLN]],[2]Dados!$D:$D,[2]Dados!$Q:$Q,"-"),_xlfn.IFS(LEFT(_xlpm.t,3)="PAS","Saco",LEFT(_xlpm.t,3)="PBT","Big Bag",TRUE,"-"))} -> Big Bag | Q84: =_xlfn.LET(_xlpm.p,_xlfn.XLOOKUP(_Shipments[[#This Row],[CLN]],[2]Dados!$D:$D,[2]Dados!$K:$K,"-"),_xlpm.n,_Shipments[[#This Row],[Qtde. sacos/palete]],IF(ISNUMBER(_xlpm.p),IF(_Shipments[[#This Row],[Embalagem]]="Big Bag",IF(ISNUMBER(_xlpm.n),_xlpm.p*_xlpm.n,"-"),_xlpm.p),"-")) -> 678.4 | R84: =IF(_Shipments[[#This Row],[Embalagem]]="Big Bag",_Shipments[[#This Row],[Qtd.]],ROUNDUP(_Shipments[[#This Row],[Qtd.]]/_Shipments[[#This Row],[Qtde. sacos/palete]],0)) -> 21 | S84: ERNANI EUSTAQUIO DE SOUSA | T84: 34991030020 | U84: BCG-7A17 | V84: MSD-4B27 | W84: G10 TRANSPORTES S.A
A85: =_xlfn.XLOOKUP(_Shipments[[#This Row],[Shipment]],[1]Report!$G:$G,[1]Report!$B:$B,"-") -> 46275.375 | B85: 7241990 | C85: 5541984190 | D85: 1 | E85: P3845VYHR-B844 | F85: 21 | G85: CORTEVA AGRISCIENCE DO BRASIL LTDA. | H85: UBERLÂNDIA | I85: MG | J85: 21 | K85: 7518218 | L85: 03P7518218 | M85: R2 | N85: =IF(_Shipments[[#This Row],[Embalagem]]="Big Bag",_Shipments[[#This Row],[Qtd.]]*_Shipments[[#This Row],[Qtde. sacos/palete]],_Shipments[[#This Row],[Qtd.]]) -> 840 | O85: =_xlfn.XLOOKUP(_Shipments[[#This Row],[CLN]],[2]Dados!$D:$D,[2]Dados!$R:$R,"-") -> 40 | P85: {=_xlfn.LET(_xlpm.t,_xlfn.XLOOKUP(_Shipments[[#This Row],[CLN]],[2]Dados!$D:$D,[2]Dados!$Q:$Q,"-"),_xlfn.IFS(LEFT(_xlpm.t,3)="PAS","Saco",LEFT(_xlpm.t,3)="PBT","Big Bag",TRUE,"-"))} -> Big Bag | Q85: =_xlfn.LET(_xlpm.p,_xlfn.XLOOKUP(_Shipments[[#This Row],[CLN]],[2]Dados!$D:$D,[2]Dados!$K:$K,"-"),_xlpm.n,_Shipments[[#This Row],[Qtde. sacos/palete]],IF(ISNUMBER(_xlpm.p),IF(_Shipments[[#This Row],[Embalagem]]="Big Bag",IF(ISNUMBER(_xlpm.n),_xlpm.p*_xlpm.n,"-"),_xlpm.p),"-")) -> 756.8 | R85: =IF(_Shipments[[#This Row],[Embalagem]]="Big Bag",_Shipments[[#This Row],[Qtd.]],ROUNDUP(_Shipments[[#This Row],[Qtd.]]/_Shipments[[#This Row],[Qtde. sacos/palete]],0)) -> 21 | S85: NATANIEL CICERO DA SILVA | T85: 34999810409 | U85: KFA-6J66 | V85: GXH-5189 | W85: G10 TRANSPORTES S.A
A86: =_xlfn.XLOOKUP(_Shipments[[#This Row],[Shipment]],[1]Report!$G:$G,[1]Report!$B:$B,"-") -> 46275.375 | B86: 7241991 | C86: 5541984191 | D86: 1 | E86: P3845VYHR-B845 | F86: 19 | G86: CORTEVA AGRISCIENCE DO BRASIL LTDA. | H86: UBERLÂNDIA | I86: MG | J86: 19 | K86: 7518200 | L86: 03P7518200 | M86: R3 | N86: =IF(_Shipments[[#This Row],[Embalagem]]="Big Bag",_Shipments[[#This Row],[Qtd.]]*_Shipments[[#This Row],[Qtde. sacos/palete]],_Shipments[[#This Row],[Qtd.]]) -> 760 | O86: =_xlfn.XLOOKUP(_Shipments[[#This Row],[CLN]],[2]Dados!$D:$D,[2]Dados!$R:$R,"-") -> 40 | P86: {=_xlfn.LET(_xlpm.t,_xlfn.XLOOKUP(_Shipments[[#This Row],[CLN]],[2]Dados!$D:$D,[2]Dados!$Q:$Q,"-"),_xlfn.IFS(LEFT(_xlpm.t,3)="PAS","Saco",LEFT(_xlpm.t,3)="PBT","Big Bag",TRUE,"-"))} -> Big Bag | Q86: =_xlfn.LET(_xlpm.p,_xlfn.XLOOKUP(_Shipments[[#This Row],[CLN]],[2]Dados!$D:$D,[2]Dados!$K:$K,"-"),_xlpm.n,_Shipments[[#This Row],[Qtde. sacos/palete]],IF(ISNUMBER(_xlpm.p),IF(_Shipments[[#This Row],[Embalagem]]="Big Bag",IF(ISNUMBER(_xlpm.n),_xlpm.p*_xlpm.n,"-"),_xlpm.p),"-")) -> 666.8 | R86: =IF(_Shipments[[#This Row],[Embalagem]]="Big Bag",_Shipments[[#This Row],[Qtd.]],ROUNDUP(_Shipments[[#This Row],[Qtd.]]/_Shipments[[#This Row],[Qtde. sacos/palete]],0)) -> 19 | S86: JOAO BRAZ DE OLIVEIRA | T86: 34991337791 | U86: GZV-6349 | V86: ONR-6845 | W86: G10 TRANSPORTES S.A
A87: =_xlfn.XLOOKUP(_Shipments[[#This Row],[Shipment]],[1]Report!$G:$G,[1]Report!$B:$B,"-") -> 46275.375 | B87: 7241991 | C87: 5541984191 | D87: 2 | E87: P3845VYHR-B841 | F87: 2 | G87: CORTEVA AGRISCIENCE DO BRASIL LTDA. | H87: UBERLÂNDIA | I87: MG | J87: 2 | K87: 7566370 | L87: 03P7566370 | M87: C2 | N87: =IF(_Shipments[[#This Row],[Embalagem]]="Big Bag",_Shipments[[#This Row],[Qtd.]]*_Shipments[[#This Row],[Qtde. sacos/palete]],_Shipments[[#This Row],[Qtd.]]) -> 80 | O87: =_xlfn.XLOOKUP(_Shipments[[#This Row],[CLN]],[2]Dados!$D:$D,[2]Dados!$R:$R,"-") -> 40 | P87: {=_xlfn.LET(_xlpm.t,_xlfn.XLOOKUP(_Shipments[[#This Row],[CLN]],[2]Dados!$D:$D,[2]Dados!$Q:$Q,"-"),_xlfn.IFS(LEFT(_xlpm.t,3)="PAS","Saco",LEFT(_xlpm.t,3)="PBT","Big Bag",TRUE,"-"))} -> Big Bag | Q87: =_xlfn.LET(_xlpm.p,_xlfn.XLOOKUP(_Shipments[[#This Row],[CLN]],[2]Dados!$D:$D,[2]Dados!$K:$K,"-"),_xlpm.n,_Shipments[[#This Row],[Qtde. sacos/palete]],IF(ISNUMBER(_xlpm.p),IF(_Shipments[[#This Row],[Embalagem]]="Big Bag",IF(ISNUMBER(_xlpm.n),_xlpm.p*_xlpm.n,"-"),_xlpm.p),"-")) -> 707.2 | R87: =IF(_Shipments[[#This Row],[Embalagem]]="Big Bag",_Shipments[[#This Row],[Qtd.]],ROUNDUP(_Shipments[[#This Row],[Qtd.]]/_Shipments[[#This Row],[Qtde. sacos/palete]],0)) -> 2 | S87: JOAO BRAZ DE OLIVEIRA | T87: 34991337791 | U87: GZV-6349 | V87: ONR-6845 | W87: G10 TRANSPORTES S.A
A88: =_xlfn.XLOOKUP(_Shipments[[#This Row],[Shipment]],[1]Report!$G:$G,[1]Report!$B:$B,"-") -> 46276.333 | B88: 7241993 | C88: 5541984192 | D88: 1 | E88: P3845VYHR-B841 | F88: 20 | G88: CORTEVA AGRISCIENCE DO BRASIL LTDA. | H88: UBERLÂNDIA | I88: MG | J88: 20 | K88: 7566370 | L88: 03P7566370 | M88: C2 | N88: =IF(_Shipments[[#This Row],[Embalagem]]="Big Bag",_Shipments[[#This Row],[Qtd.]]*_Shipments[[#This Row],[Qtde. sacos/palete]],_Shipments[[#This Row],[Qtd.]]) -> 800 | O88: =_xlfn.XLOOKUP(_Shipments[[#This Row],[CLN]],[2]Dados!$D:$D,[2]Dados!$R:$R,"-") -> 40 | P88: {=_xlfn.LET(_xlpm.t,_xlfn.XLOOKUP(_Shipments[[#This Row],[CLN]],[2]Dados!$D:$D,[2]Dados!$Q:$Q,"-"),_xlfn.IFS(LEFT(_xlpm.t,3)="PAS","Saco",LEFT(_xlpm.t,3)="PBT","Big Bag",TRUE,"-"))} -> Big Bag | Q88: =_xlfn.LET(_xlpm.p,_xlfn.XLOOKUP(_Shipments[[#This Row],[CLN]],[2]Dados!$D:$D,[2]Dados!$K:$K,"-"),_xlpm.n,_Shipments[[#This Row],[Qtde. sacos/palete]],IF(ISNUMBER(_xlpm.p),IF(_Shipments[[#This Row],[Embalagem]]="Big Bag",IF(ISNUMBER(_xlpm.n),_xlpm.p*_xlpm.n,"-"),_xlpm.p),"-")) -> 707.2 | R88: =IF(_Shipments[[#This Row],[Embalagem]]="Big Bag",_Shipments[[#This Row],[Qtd.]],ROUNDUP(_Shipments[[#This Row],[Qtd.]]/_Shipments[[#This Row],[Qtde. sacos/palete]],0)) -> 20 | S88: ERNANI EUSTAQUIO DE SOUSA | T88: 34991030020 | U88: BCG-7A17 | V88: MSD-4B27 | W88: G10 TRANSPORTES S.A
... A121: =_xlfn.XLOOKUP(_Shipments[[#This Row],[Shipment]],[1]Report!$G:$G,[1]Report!$B:$B,"-") -> 46279.375 | B121: 7242807 | C121: 5541984869 | D121: 1 | E121: P3845VYHR-B841 | F121: 21 | G121: CORTEVA AGRISCIENCE DO BRASIL LTDA. | H121: UBERLÂNDIA | I121: MG | J121: 21 | K121: 7518153 | L121: 03P7518153 | M121: C1 | N121: =IF(_Shipments[[#This Row],[Embalagem]]="Big Bag",_Shipments[[#This Row],[Qtd.]]*_Shipments[[#This Row],[Qtde. sacos/palete]],_Shipments[[#This Row],[Qtd.]]) -> 840 | O121: =_xlfn.XLOOKUP(_Shipments[[#This Row],[CLN]],[2]Dados!$D:$D,[2]Dados!$R:$R,"-") -> 40 | P121: {=_xlfn.LET(_xlpm.t,_xlfn.XLOOKUP(_Shipments[[#This Row],[CLN]],[2]Dados!$D:$D,[2]Dados!$Q:$Q,"-"),_xlfn.IFS(LEFT(_xlpm.t,3)="PAS","Saco",LEFT(_xlpm.t,3)="PBT","Big Bag",TRUE,"-"))} -> Big Bag | Q121: =_xlfn.LET(_xlpm.p,_xlfn.XLOOKUP(_Shipments[[#This Row],[CLN]],[2]Dados!$D:$D,[2]Dados!$K:$K,"-"),_xlpm.n,_Shipments[[#This Row],[Qtde. sacos/palete]],IF(ISNUMBER(_xlpm.p),IF(_Shipments[[#This Row],[Embalagem]]="Big Bag",IF(ISNUMBER(_xlpm.n),_xlpm.p*_xlpm.n,"-"),_xlpm.p),"-")) -> 796.4 | R121: =IF(_Shipments[[#This Row],[Embalagem]]="Big Bag",_Shipments[[#This Row],[Qtd.]],ROUNDUP(_Shipments[[#This Row],[Qtd.]]/_Shipments[[#This Row],[Qtde. sacos/palete]],0)) -> 21 | S121: LINDOMAR MOREIRA DE LIMA | T121: 34991718554 | U121: NFF-7194 | V121: ONC-5436 | W121: G10 TRANSPORTES S.A
A122: =_xlfn.XLOOKUP(_Shipments[[#This Row],[Shipment]],[1]Report!$G:$G,[1]Report!$B:$B,"-") -> 46280.333 | B122: 7242808 | C122: 5541984875 | D122: 1 | E122: P3845VYHR-B841 | F122: 9 | G122: CORTEVA AGRISCIENCE DO BRASIL LTDA. | H122: UBERLÂNDIA | I122: MG | J122: 9 | K122: 7518153 | L122: 03P7518153 | M122: C1 | N122: =IF(_Shipments[[#This Row],[Embalagem]]="Big Bag",_Shipments[[#This Row],[Qtd.]]*_Shipments[[#This Row],[Qtde. sacos/palete]],_Shipments[[#This Row],[Qtd.]]) -> 360 | O122: =_xlfn.XLOOKUP(_Shipments[[#This Row],[CLN]],[2]Dados!$D:$D,[2]Dados!$R:$R,"-") -> 40 | P122: {=_xlfn.LET(_xlpm.t,_xlfn.XLOOKUP(_Shipments[[#This Row],[CLN]],[2]Dados!$D:$D,[2]Dados!$Q:$Q,"-"),_xlfn.IFS(LEFT(_xlpm.t,3)="PAS","Saco",LEFT(_xlpm.t,3)="PBT","Big Bag",TRUE,"-"))} -> Big Bag | Q122: =_xlfn.LET(_xlpm.p,_xlfn.XLOOKUP(_Shipments[[#This Row],[CLN]],[2]Dados!$D:$D,[2]Dados!$K:$K,"-"),_xlpm.n,_Shipments[[#This Row],[Qtde. sacos/palete]],IF(ISNUMBER(_xlpm.p),IF(_Shipments[[#This Row],[Embalagem]]="Big Bag",IF(ISNUMBER(_xlpm.n),_xlpm.p*_xlpm.n,"-"),_xlpm.p),"-")) -> 796.4 | R122: =IF(_Shipments[[#This Row],[Embalagem]]="Big Bag",_Shipments[[#This Row],[Qtd.]],ROUNDUP(_Shipments[[#This Row],[Qtd.]]/_Shipments[[#This Row],[Qtde. sacos/palete]],0)) -> 9 | S122: MAURO FRANCISCO PEREIRA | T122: (34) 9 9916-1847 | U122: NZA-0F96 | V122: SYB-9E72 | W122: G10 TRANSPORTES S.A
A123: =_xlfn.XLOOKUP(_Shipments[[#This Row],[Shipment]],[1]Report!$G:$G,[1]Report!$B:$B,"-") -> 46280.333 | B123: 7242808 | C123: 5541984875 | D123: 2 | E123: P3845VYHR-B841 | F123: 12 | G123: CORTEVA AGRISCIENCE DO BRASIL LTDA. | H123: UBERLÂNDIA | I123: MG | J123: 12 | K123: 7518161 | L123: 03P7518161 | M123: C1 | N123: =IF(_Shipments[[#This Row],[Embalagem]]="Big Bag",_Shipments[[#This Row],[Qtd.]]*_Shipments[[#This Row],[Qtde. sacos/palete]],_Shipments[[#This Row],[Qtd.]]) -> 480 | O123: =_xlfn.XLOOKUP(_Shipments[[#This Row],[CLN]],[2]Dados!$D:$D,[2]Dados!$R:$R,"-") -> 40 | P123: {=_xlfn.LET(_xlpm.t,_xlfn.XLOOKUP(_Shipments[[#This Row],[CLN]],[2]Dados!$D:$D,[2]Dados!$Q:$Q,"-"),_xlfn.IFS(LEFT(_xlpm.t,3)="PAS","Saco",LEFT(_xlpm.t,3)="PBT","Big Bag",TRUE,"-"))} -> Big Bag | Q123: =_xlfn.LET(_xlpm.p,_xlfn.XLOOKUP(_Shipments[[#This Row],[CLN]],[2]Dados!$D:$D,[2]Dados!$K:$K,"-"),_xlpm.n,_Shipments[[#This Row],[Qtde. sacos/palete]],IF(ISNUMBER(_xlpm.p),IF(_Shipments[[#This Row],[Embalagem]]="Big Bag",IF(ISNUMBER(_xlpm.n),_xlpm.p*_xlpm.n,"-"),_xlpm.p),"-")) -> 788 | R123: =IF(_Shipments[[#This Row],[Embalagem]]="Big Bag",_Shipments[[#This Row],[Qtd.]],ROUNDUP(_Shipments[[#This Row],[Qtd.]]/_Shipments[[#This Row],[Qtde. sacos/palete]],0)) -> 12 | S123: MAURO FRANCISCO PEREIRA | T123: (34) 9 9916-1847 | U123: NZA-0F96 | V123: SYB-9E72 | W123: G10 TRANSPORTES S.A
A124: =_xlfn.XLOOKUP(_Shipments[[#This Row],[Shipment]],[1]Report!$G:$G,[1]Report!$B:$B,"-") -> 46280.333 | B124: 7242811 | C124: 5541984876 | D124: 1 | E124: P3845VYHR-B841 | F124: 20 | G124: CORTEVA AGRISCIENCE DO BRASIL LTDA. | H124: UBERLÂNDIA | I124: MG | J124: 20 | K124: 7518161 | L124: 03P7518161 | M124: C1 | N124: =IF(_Shipments[[#This Row],[Embalagem]]="Big Bag",_Shipments[[#This Row],[Qtd.]]*_Shipments[[#This Row],[Qtde. sacos/palete]],_Shipments[[#This Row],[Qtd.]]) -> 800 | O124: =_xlfn.XLOOKUP(_Shipments[[#This Row],[CLN]],[2]Dados!$D:$D,[2]Dados!$R:$R,"-") -> 40 | P124: {=_xlfn.LET(_xlpm.t,_xlfn.XLOOKUP(_Shipments[[#This Row],[CLN]],[2]Dados!$D:$D,[2]Dados!$Q:$Q,"-"),_xlfn.IFS(LEFT(_xlpm.t,3)="PAS","Saco",LEFT(_xlpm.t,3)="PBT","Big Bag",TRUE,"-"))} -> Big Bag | Q124: =_xlfn.LET(_xlpm.p,_xlfn.XLOOKUP(_Shipments[[#This Row],[CLN]],[2]Dados!$D:$D,[2]Dados!$K:$K,"-"),_xlpm.n,_Shipments[[#This Row],[Qtde. sacos/palete]],IF(ISNUMBER(_xlpm.p),IF(_Shipments[[#This Row],[Embalagem]]="Big Bag",IF(ISNUMBER(_xlpm.n),_xlpm.p*_xlpm.n,"-"),_xlpm.p),"-")) -> 788 | R124: =IF(_Shipments[[#This Row],[Embalagem]]="Big Bag",_Shipments[[#This Row],[Qtd.]],ROUNDUP(_Shipments[[#This Row],[Qtd.]]/_Shipments[[#This Row],[Qtde. sacos/palete]],0)) -> 20 | S124: JOSE VALDECIR CORREA | T124: (44) 9 9159-5938 | U124: BCO-0157 | V124: RHR-3J00 | W124: G10 TRANSPORTES S.A
A125: =_xlfn.XLOOKUP(_Shipments[[#This Row],[Shipment]],[1]Report!$G:$G,[1]Report!$B:$B,"-") -> 46280.375 | B125: 7242816 | C125: 5541984880 | D125: 1 | E125: P3845VYHR-B841 | F125: 21 | G125: CORTEVA AGRISCIENCE DO BRASIL LTDA. | H125: UBERLÂNDIA | I125: MG | J125: 21 | K125: 7561729 | L125: 03P7561729 | M125: C2 | N125: =IF(_Shipments[[#This Row],[Embalagem]]="Big Bag",_Shipments[[#This Row],[Qtd.]]*_Shipments[[#This Row],[Qtde. sacos/palete]],_Shipments[[#This Row],[Qtd.]]) -> 840 | O125: =_xlfn.XLOOKUP(_Shipments[[#This Row],[CLN]],[2]Dados!$D:$D,[2]Dados!$R:$R,"-") -> 40 | P125: {=_xlfn.LET(_xlpm.t,_xlfn.XLOOKUP(_Shipments[[#This Row],[CLN]],[2]Dados!$D:$D,[2]Dados!$Q:$Q,"-"),_xlfn.IFS(LEFT(_xlpm.t,3)="PAS","Saco",LEFT(_xlpm.t,3)="PBT","Big Bag",TRUE,"-"))} -> Big Bag | Q125: =_xlfn.LET(_xlpm.p,_xlfn.XLOOKUP(_Shipments[[#This Row],[CLN]],[2]Dados!$D:$D,[2]Dados!$K:$K,"-"),_xlpm.n,_Shipments[[#This Row],[Qtde. sacos/palete]],IF(ISNUMBER(_xlpm.p),IF(_Shipments[[#This Row],[Embalagem]]="Big Bag",IF(ISNUMBER(_xlpm.n),_xlpm.p*_xlpm.n,"-"),_xlpm.p),"-")) -> 698.8 | R125: =IF(_Shipments[[#This Row],[Embalagem]]="Big Bag",_Shipments[[#This Row],[Qtd.]],ROUNDUP(_Shipments[[#This Row],[Qtd.]]/_Shipments[[#This Row],[Qtde. sacos/palete]],0)) -> 21 | S125: JOAO BRAZ DE OLIVEIRA | T125: 34991337791 | U125: GZV-6349 | V125: ONR-6845 | W125: G10 TRANSPORTES S.A
A126: =_xlfn.XLOOKUP(_Shipments[[#This Row],[Shipment]],[1]Report!$G:$G,[1]Report!$B:$B,"-") -> 46280.375 | B126: 7242819 | C126: 5541984881 | D126: 1 | E126: P3845VYHR-B841 | F126: 5 | G126: CORTEVA AGRISCIENCE DO BRASIL LTDA. | H126: UBERLÂNDIA | I126: MG | J126: 5 | K126: 7561729 | L126: 03P7561729 | M126: C2 | N126: =IF(_Shipments[[#This Row],[Embalagem]]="Big Bag",_Shipments[[#This Row],[Qtd.]]*_Shipments[[#This Row],[Qtde. sacos/palete]],_Shipments[[#This Row],[Qtd.]]) -> 200 | O126: =_xlfn.XLOOKUP(_Shipments[[#This Row],[CLN]],[2]Dados!$D:$D,[2]Dados!$R:$R,"-") -> 40 | P126: {=_xlfn.LET(_xlpm.t,_xlfn.XLOOKUP(_Shipments[[#This Row],[CLN]],[2]Dados!$D:$D,[2]Dados!$Q:$Q,"-"),_xlfn.IFS(LEFT(_xlpm.t,3)="PAS","Saco",LEFT(_xlpm.t,3)="PBT","Big Bag",TRUE,"-"))} -> Big Bag | Q126: =_xlfn.LET(_xlpm.p,_xlfn.XLOOKUP(_Shipments[[#This Row],[CLN]],[2]Dados!$D:$D,[2]Dados!$K:$K,"-"),_xlpm.n,_Shipments[[#This Row],[Qtde. sacos/palete]],IF(ISNUMBER(_xlpm.p),IF(_Shipments[[#This Row],[Embalagem]]="Big Bag",IF(ISNUMBER(_xlpm.n),_xlpm.p*_xlpm.n,"-"),_xlpm.p),"-")) -> 698.8 | R126: =IF(_Shipments[[#This Row],[Embalagem]]="Big Bag",_Shipments[[#This Row],[Qtd.]],ROUNDUP(_Shipments[[#This Row],[Qtd.]]/_Shipments[[#This Row],[Qtde. sacos/palete]],0)) -> 5 | S126: NATANIEL CICERO DA SILVA | T126: 34999810409 | U126: KFA-6J66 | V126: GXH-5189 | W126: G10 TRANSPORTES S.A
A127: =_xlfn.XLOOKUP(_Shipments[[#This Row],[Shipment]],[1]Report!$G:$G,[1]Report!$B:$B,"-") -> 46280.375 | B127: 7242819 | C127: 5541984881 | D127: 2 | E127: P3845VYHR-B841 | F127: 16 | G127: CORTEVA AGRISCIENCE DO BRASIL LTDA. | H127: UBERLÂNDIA | I127: MG | J127: 16 | K127: 7518139 | L127: 03P7518139 | M127: C1 | N127: =IF(_Shipments[[#This Row],[Embalagem]]="Big Bag",_Shipments[[#This Row],[Qtd.]]*_Shipments[[#This Row],[Qtde. sacos/palete]],_Shipments[[#This Row],[Qtd.]]) -> 640 | O127: =_xlfn.XLOOKUP(_Shipments[[#This Row],[CLN]],[2]Dados!$D:$D,[2]Dados!$R:$R,"-") -> 40 | P127: {=_xlfn.LET(_xlpm.t,_xlfn.XLOOKUP(_Shipments[[#This Row],[CLN]],[2]Dados!$D:$D,[2]Dados!$Q:$Q,"-"),_xlfn.IFS(LEFT(_xlpm.t,3)="PAS","Saco",LEFT(_xlpm.t,3)="PBT","Big Bag",TRUE,"-"))} -> Big Bag | Q127: =_xlfn.LET(_xlpm.p,_xlfn.XLOOKUP(_Shipments[[#This Row],[CLN]],[2]Dados!$D:$D,[2]Dados!$K:$K,"-"),_xlpm.n,_Shipments[[#This Row],[Qtde. sacos/palete]],IF(ISNUMBER(_xlpm.p),IF(_Shipments[[#This Row],[Embalagem]]="Big Bag",IF(ISNUMBER(_xlpm.n),_xlpm.p*_xlpm.n,"-"),_xlpm.p),"-")) -> 673.6 | R127: =IF(_Shipments[[#This Row],[Embalagem]]="Big Bag",_Shipments[[#This Row],[Qtd.]],ROUNDUP(_Shipments[[#This Row],[Qtd.]]/_Shipments[[#This Row],[Qtde. sacos/palete]],0)) -> 16 | S127: NATANIEL CICERO DA SILVA | T127: 34999810409 | U127: KFA-6J66 | V127: GXH-5189 | W127: G10 TRANSPORTES S.A
A128: =_xlfn.XLOOKUP(_Shipments[[#This Row],[Shipment]],[1]Report!$G:$G,[1]Report!$B:$B,"-") -> 46281.333 | B128: 7242822 | C128: 5541984903 | D128: 1 | E128: P3845VYHR-B841 | F128: 21 | G128: CORTEVA AGRISCIENCE DO BRASIL LTDA. | H128: UBERLÂNDIA | I128: MG | J128: 21 | K128: 7518139 | L128: 03P7518139 | M128: C1 | N128: =IF(_Shipments[[#This Row],[Embalagem]]="Big Bag",_Shipments[[#This Row],[Qtd.]]*_Shipments[[#This Row],[Qtde. sacos/palete]],_Shipments[[#This Row],[Qtd.]]) -> 840 | O128: =_xlfn.XLOOKUP(_Shipments[[#This Row],[CLN]],[2]Dados!$D:$D,[2]Dados!$R:$R,"-") -> 40 | P128: {=_xlfn.LET(_xlpm.t,_xlfn.XLOOKUP(_Shipments[[#This Row],[CLN]],[2]Dados!$D:$D,[2]Dados!$Q:$Q,"-"),_xlfn.IFS(LEFT(_xlpm.t,3)="PAS","Saco",LEFT(_xlpm.t,3)="PBT","Big Bag",TRUE,"-"))} -> Big Bag | Q128: =_xlfn.LET(_xlpm.p,_xlfn.XLOOKUP(_Shipments[[#This Row],[CLN]],[2]Dados!$D:$D,[2]Dados!$K:$K,"-"),_xlpm.n,_Shipments[[#This Row],[Qtde. sacos/palete]],IF(ISNUMBER(_xlpm.p),IF(_Shipments[[#This Row],[Embalagem]]="Big Bag",IF(ISNUMBER(_xlpm.n),_xlpm.p*_xlpm.n,"-"),_xlpm.p),"-")) -> 673.6 | R128: =IF(_Shipments[[#This Row],[Embalagem]]="Big Bag",_Shipments[[#This Row],[Qtd.]],ROUNDUP(_Shipments[[#This Row],[Qtd.]]/_Shipments[[#This Row],[Qtde. sacos/palete]],0)) -> 21 | S128: RODRIGO DOS REIS VIEIRA | T128: 34997330803 | U128: HZM-8D37 | V128: OLF-8C62 | W128: G10 TRANSPORTES S.A
A129: =_xlfn.XLOOKUP(_Shipments[[#This Row],[Shipment]],[1]Report!$G:$G,[1]Report!$B:$B,"-") -> 46281.333 | B129: 7242827 | C129: 5541984905 | D129: 1 | E129: P3845VYHR-B841 | F129: 2 | G129: CORTEVA AGRISCIENCE DO BRASIL LTDA. | H129: UBERLÂNDIA | I129: MG | J129: 2 | K129: 7518139 | L129: 03P7518139 | M129: C1 | N129: =IF(_Shipments[[#This Row],[Embalagem]]="Big Bag",_Shipments[[#This Row],[Qtd.]]*_Shipments[[#This Row],[Qtde. sacos/palete]],_Shipments[[#This Row],[Qtd.]]) -> 80 | O129: =_xlfn.XLOOKUP(_Shipments[[#This Row],[CLN]],[2]Dados!$D:$D,[2]Dados!$R:$R,"-") -> 40 | P129: {=_xlfn.LET(_xlpm.t,_xlfn.XLOOKUP(_Shipments[[#This Row],[CLN]],[2]Dados!$D:$D,[2]Dados!$Q:$Q,"-"),_xlfn.IFS(LEFT(_xlpm.t,3)="PAS","Saco",LEFT(_xlpm.t,3)="PBT","Big Bag",TRUE,"-"))} -> Big Bag | Q129: =_xlfn.LET(_xlpm.p,_xlfn.XLOOKUP(_Shipments[[#This Row],[CLN]],[2]Dados!$D:$D,[2]Dados!$K:$K,"-"),_xlpm.n,_Shipments[[#This Row],[Qtde. sacos/palete]],IF(ISNUMBER(_xlpm.p),IF(_Shipments[[#This Row],[Embalagem]]="Big Bag",IF(ISNUMBER(_xlpm.n),_xlpm.p*_xlpm.n,"-"),_xlpm.p),"-")) -> 673.6 | R129: =IF(_Shipments[[#This Row],[Embalagem]]="Big Bag",_Shipments[[#This Row],[Qtd.]],ROUNDUP(_Shipments[[#This Row],[Qtd.]]/_Shipments[[#This Row],[Qtde. sacos/palete]],0)) -> 2 | S129: ERNANI EUSTAQUIO DE SOUSA | T129: 34991030020 | U129: BCG-7A17 | V129: MSD-4B27 | W129: G10 TRANSPORTES S.A
A130: =_xlfn.XLOOKUP(_Shipments[[#This Row],[Shipment]],[1]Report!$G:$G,[1]Report!$B:$B,"-") -> 46281.333 | B130: 7242827 | C130: 5541984905 | D130: 2 | E130: P3845VYHR-B841 | F130: 8 | G130: CORTEVA AGRISCIENCE DO BRASIL LTDA. | H130: UBERLÂNDIA | I130: MG | J130: 8 | K130: 7518148 | L130: 03P7518148 | M130: C1 | N130: =IF(_Shipments[[#This Row],[Embalagem]]="Big Bag",_Shipments[[#This Row],[Qtd.]]*_Shipments[[#This Row],[Qtde. sacos/palete]],_Shipments[[#This Row],[Qtd.]]) -> 320 | O130: =_xlfn.XLOOKUP(_Shipments[[#This Row],[CLN]],[2]Dados!$D:$D,[2]Dados!$R:$R,"-") -> 40 | P130: {=_xlfn.LET(_xlpm.t,_xlfn.XLOOKUP(_Shipments[[#This Row],[CLN]],[2]Dados!$D:$D,[2]Dados!$Q:$Q,"-"),_xlfn.IFS(LEFT(_xlpm.t,3)="PAS","Saco",LEFT(_xlpm.t,3)="PBT","Big Bag",TRUE,"-"))} -> Big Bag | Q130: =_xlfn.LET(_xlpm.p,_xlfn.XLOOKUP(_Shipments[[#This Row],[CLN]],[2]Dados!$D:$D,[2]Dados!$K:$K,"-"),_xlpm.n,_Shipments[[#This Row],[Qtde. sacos/palete]],IF(ISNUMBER(_xlpm.p),IF(_Shipments[[#This Row],[Embalagem]]="Big Bag",IF(ISNUMBER(_xlpm.n),_xlpm.p*_xlpm.n,"-"),_xlpm.p),"-")) -> 787.6 | R130: =IF(_Shipments[[#This Row],[Embalagem]]="Big Bag",_Shipments[[#This Row],[Qtd.]],ROUNDUP(_Shipments[[#This Row],[Qtd.]]/_Shipments[[#This Row],[Qtde. sacos/palete]],0)) -> 8 | S130: ERNANI EUSTAQUIO DE SOUSA | T130: 34991030020 | U130: BCG-7A17 | V130: MSD-4B27 | W130: G10 TRANSPORTES S.A
A131: =_xlfn.XLOOKUP(_Shipments[[#This Row],[Shipment]],[1]Report!$G:$G,[1]Report!$B:$B,"-") -> 46281.333 | B131: 7242827 | C131: 5541984905 | D131: 3 | E131: P3845VYHR-B841 | F131: 11 | G131: CORTEVA AGRISCIENCE DO BRASIL LTDA. | H131: UBERLÂNDIA | I131: MG | J131: 11 | K131: 7518156 | L131: 03P7518156 | M131: C1 | N131: =IF(_Shipments[[#This Row],[Embalagem]]="Big Bag",_Shipments[[#This Row],[Qtd.]]*_Shipments[[#This Row],[Qtde. sacos/palete]],_Shipments[[#This Row],[Qtd.]]) -> 440 | O131: =_xlfn.XLOOKUP(_Shipments[[#This Row],[CLN]],[2]Dados!$D:$D,[2]Dados!$R:$R,"-") -> 40 | P131: {=_xlfn.LET(_xlpm.t,_xlfn.XLOOKUP(_Shipments[[#This Row],[CLN]],[2]Dados!$D:$D,[2]Dados!$Q:$Q,"-"),_xlfn.IFS(LEFT(_xlpm.t,3)="PAS","Saco",LEFT(_xlpm.t,3)="PBT","Big Bag",TRUE,"-"))} -> Big Bag | Q131: =_xlfn.LET(_xlpm.p,_xlfn.XLOOKUP(_Shipments[[#This Row],[CLN]],[2]Dados!$D:$D,[2]Dados!$K:$K,"-"),_xlpm.n,_Shipments[[#This Row],[Qtde. sacos/palete]],IF(ISNUMBER(_xlpm.p),IF(_Shipments[[#This Row],[Embalagem]]="Big Bag",IF(ISNUMBER(_xlpm.n),_xlpm.p*_xlpm.n,"-"),_xlpm.p),"-")) -> 789.6 | R131: =IF(_Shipments[[#This Row],[Embalagem]]="Big Bag",_Shipments[[#This Row],[Qtd.]],ROUNDUP(_Shipments[[#This Row],[Qtd.]]/_Shipments[[#This Row],[Qtde. sacos/palete]],0)) -> 11 | S131: ERNANI EUSTAQUIO DE SOUSA | T131: 34991030020 | U131: BCG-7A17 | V131: MSD-4B27 | W131: G10 TRANSPORTES S.A
A132: =_xlfn.XLOOKUP(_Shipments[[#This Row],[Shipment]],[1]Report!$G:$G,[1]Report!$B:$B,"-") -> 46281.375 | B132: 7242830 | C132: 5541984913 | D132: 1 | E132: P3845VYHR-B841 | F132: 21 | G132: CORTEVA AGRISCIENCE DO BRASIL LTDA. | H132: UBERLÂNDIA | I132: MG | J132: 21 | K132: 7518148 | L132: 03P7518148 | M132: C1 | N132: =IF(_Shipments[[#This Row],[Embalagem]]="Big Bag",_Shipments[[#This Row],[Qtd.]]*_Shipments[[#This Row],[Qtde. sacos/palete]],_Shipments[[#This Row],[Qtd.]]) -> 840 | O132: =_xlfn.XLOOKUP(_Shipments[[#This Row],[CLN]],[2]Dados!$D:$D,[2]Dados!$R:$R,"-") -> 40 | P132: {=_xlfn.LET(_xlpm.t,_xlfn.XLOOKUP(_Shipments[[#This Row],[CLN]],[2]Dados!$D:$D,[2]Dados!$Q:$Q,"-"),_xlfn.IFS(LEFT(_xlpm.t,3)="PAS","Saco",LEFT(_xlpm.t,3)="PBT","Big Bag",TRUE,"-"))} -> Big Bag | Q132: =_xlfn.LET(_xlpm.p,_xlfn.XLOOKUP(_Shipments[[#This Row],[CLN]],[2]Dados!$D:$D,[2]Dados!$K:$K,"-"),_xlpm.n,_Shipments[[#This Row],[Qtde. sacos/palete]],IF(ISNUMBER(_xlpm.p),IF(_Shipments[[#This Row],[Embalagem]]="Big Bag",IF(ISNUMBER(_xlpm.n),_xlpm.p*_xlpm.n,"-"),_xlpm.p),"-")) -> 787.6 | R132: =IF(_Shipments[[#This Row],[Embalagem]]="Big Bag",_Shipments[[#This Row],[Qtd.]],ROUNDUP(_Shipments[[#This Row],[Qtd.]]/_Shipments[[#This Row],[Qtde. sacos/palete]],0)) -> 21 | S132: DANIEL HENRIQUE DE SOUSA | T132: 34996968579 | U132: JDP-0H00 | V132: QNE-8537 | W132: G10 TRANSPORTES S.A
A133: =_xlfn.XLOOKUP(_Shipments[[#This Row],[Shipment]],[1]Report!$G:$G,[1]Report!$B:$B,"-") -> 46281.375 | B133: 7242833 | C133: 5541984915 | D133: 1 | E133: P3845VYHR-B841 | F133: 20 | G133: CORTEVA AGRISCIENCE DO BRASIL LTDA. | H133: UBERLÂNDIA | I133: MG | J133: 20 | K133: 7518156 | L133: 03P7518156 | M133: C1 | N133: =IF(_Shipments[[#This Row],[Embalagem]]="Big Bag",_Shipments[[#This Row],[Qtd.]]*_Shipments[[#This Row],[Qtde. sacos/palete]],_Shipments[[#This Row],[Qtd.]]) -> 800 | O133: =_xlfn.XLOOKUP(_Shipments[[#This Row],[CLN]],[2]Dados!$D:$D,[2]Dados!$R:$R,"-") -> 40 | P133: {=_xlfn.LET(_xlpm.t,_xlfn.XLOOKUP(_Shipments[[#This Row],[CLN]],[2]Dados!$D:$D,[2]Dados!$Q:$Q,"-"),_xlfn.IFS(LEFT(_xlpm.t,3)="PAS","Saco",LEFT(_xlpm.t,3)="PBT","Big Bag",TRUE,"-"))} -> Big Bag | Q133: =_xlfn.LET(_xlpm.p,_xlfn.XLOOKUP(_Shipments[[#This Row],[CLN]],[2]Dados!$D:$D,[2]Dados!$K:$K,"-"),_xlpm.n,_Shipments[[#This Row],[Qtde. sacos/palete]],IF(ISNUMBER(_xlpm.p),IF(_Shipments[[#This Row],[Embalagem]]="Big Bag",IF(ISNUMBER(_xlpm.n),_xlpm.p*_xlpm.n,"-"),_xlpm.p),"-")) -> 789.6 | R133: =IF(_Shipments[[#This Row],[Embalagem]]="Big Bag",_Shipments[[#This Row],[Qtd.]],ROUNDUP(_Shipments[[#This Row],[Qtd.]]/_Shipments[[#This Row],[Qtde. sacos/palete]],0)) -> 20 | S133: RODRIGO DOS REIS VIEIRA | T133: 34997330803 | U133: HZM-8D37 | V133: OLF-8C62 | W133: G10 TRANSPORTES S.A
A134: =_xlfn.XLOOKUP(_Shipments[[#This Row],[Shipment]],[1]Report!$G:$G,[1]Report!$B:$B,"-") -> 46282.333 | B134: 7242836 | C134: 5541984917 | D134: 1 | E134: P3845VYHR-B845 | F134: 21 | G134: CORTEVA AGRISCIENCE DO BRASIL LTDA. | H134: UBERLÂNDIA | I134: MG | J134: 21 | K134: 7518204 | L134: 03P7518204 | M134: R3 | N134: =IF(_Shipments[[#This Row],[Embalagem]]="Big Bag",_Shipments[[#This Row],[Qtd.]]*_Shipments[[#This Row],[Qtde. sacos/palete]],_Shipments[[#This Row],[Qtd.]]) -> 840 | O134: =_xlfn.XLOOKUP(_Shipments[[#This Row],[CLN]],[2]Dados!$D:$D,[2]Dados!$R:$R,"-") -> 40 | P134: {=_xlfn.LET(_xlpm.t,_xlfn.XLOOKUP(_Shipments[[#This Row],[CLN]],[2]Dados!$D:$D,[2]Dados!$Q:$Q,"-"),_xlfn.IFS(LEFT(_xlpm.t,3)="PAS","Saco",LEFT(_xlpm.t,3)="PBT","Big Bag",TRUE,"-"))} -> Big Bag | Q134: =_xlfn.LET(_xlpm.p,_xlfn.XLOOKUP(_Shipments[[#This Row],[CLN]],[2]Dados!$D:$D,[2]Dados!$K:$K,"-"),_xlpm.n,_Shipments[[#This Row],[Qtde. sacos/palete]],IF(ISNUMBER(_xlpm.p),IF(_Shipments[[#This Row],[Embalagem]]="Big Bag",IF(ISNUMBER(_xlpm.n),_xlpm.p*_xlpm.n,"-"),_xlpm.p),"-")) -> 667.6 | R134: =IF(_Shipments[[#This Row],[Embalagem]]="Big Bag",_Shipments[[#This Row],[Qtd.]],ROUNDUP(_Shipments[[#This Row],[Qtd.]]/_Shipments[[#This Row],[Qtde. sacos/palete]],0)) -> 21 | S134: JULIO CESAR DE OLIVEIRA | T134: 34999248710 | U134: AZN-6580 | V134: ORA-1733 | W134: G10 TRANSPORTES S.A
...

Sheet _Shipments
A1: Data | B1: Shipment | C1: Delivery | D1: Item | E1: Material | F1: Qtd. | G1: Descr. Cliente | H1: Cidade | I1: Estado | J1: Qtde. Sel. | K1: Lote | L1: CLN | M1: Peneira | N1: Sacos total (Jumbo Convertidos) | O1: Qtde. sacos/palete | P1: Embalagem | Q1: Peso | R1: Qtde. Total de Paletes | S1: Motorista | T1: Telefone | U1: Placa Cavalo | V1: Placa Carreta | W1: Transportadora | Y1: Parâmetros
A2: =_xlfn.XLOOKUP(_Shipments[[#This Row],[Shipment]],[1]Report!$G:$G,[1]Report!$B:$B,"-") -> 46260.333 | B2: 7240103 | C2: 5541981925 | D2: 1 | E2: P3845VYHR-B822 | F2: 987 | G2: CORTEVA AGRISCIENCE DO BRASIL LTDA. | H2: APARECIDA DE GOIÂNIA | I2: GO | J2: 987 | K2: 7520918 | L2: 03P7520918 | M2: C3 | N2: =IF(_Shipments[[#This Row],[Embalagem]]="Big Bag",_Shipments[[#This Row],[Qtd.]]*_Shipments[[#This Row],[Qtde. sacos/palete]],_Shipments[[#This Row],[Qtd.]]) -> 987 | O2: =_xlfn.XLOOKUP(_Shipments[[#This Row],[CLN]],[2]Dados!$D:$D,[2]Dados!$R:$R,"-") -> 75 | P2: {=_xlfn.LET(_xlpm.t,_xlfn.XLOOKUP(_Shipments[[#This Row],[CLN]],[2]Dados!$D:$D,[2]Dados!$Q:$Q,"-"),_xlfn.IFS(LEFT(_xlpm.t,3)="PAS","Saco",LEFT(_xlpm.t,3)="PBT","Big Bag",TRUE,"-"))} -> Saco | Q2: =_xlfn.LET(_xlpm.p,_xlfn.XLOOKUP(_Shipments[[#This Row],[CLN]],[2]Dados!$D:$D,[2]Dados!$K:$K,"-"),_xlpm.n,_Shipments[[#This Row],[Qtde. sacos/palete]],IF(ISNUMBER(_xlpm.p),IF(_Shipments[[#This Row],[Embalagem]]="Big Bag",IF(ISNUMBER(_xlpm.n),_xlpm.p*_xlpm.n,"-"),_xlpm.p),"-")) -> 12.16 | R2: =IF(_Shipments[[#This Row],[Embalagem]]="Big Bag",_Shipments[[#This Row],[Qtd.]],ROUNDUP(_Shipments[[#This Row],[Qtd.]]/_Shipments[[#This Row],[Qtde. sacos/palete]],0)) -> 14 | S2: ECIO CRISTINO FERREIRA | T2: 34992119997 | U2: QDC-5910 | V2: HJC-1938 | W2: G10 TRANSPORTES S.A | Y2: {=_xlfn.DROP(_xlfn.UNIQUE(_xlfn._xlws.FILTER('_Shipments'!B:B,'_Shipments'!B:B<>"")),1)} -> 7240103
A3: =_xlfn.XLOOKUP(_Shipments[[#This Row],[Shipment]],[1]Report!$G:$G,[1]Report!$B:$B,"-") -> 46260.333 | B3: 7240103 | C3: 5541981925 | D3: 2 | E3: P3845VYHR-B825 | F3: 36 | G3: CORTEVA AGRISCIENCE DO BRASIL LTDA. | H3: APARECIDA DE GOIÂNIA | I3: GO | J3: 36 | K3: 7520947 | L3: 03P7520947 | M3: R3 | N3: =IF(_Shipments[[#This Row],[Embalagem]]="Big Bag",_Shipments[[#This Row],[Qtd.]]*_Shipments[[#This Row],[Qtde. sacos/palete]],_Shipments[[#This Row],[Qtd.]]) -> 36 | O3: =_xlfn.XLOOKUP(_Shipments[[#This Row],[CLN]],[2]Dados!$D:$D,[2]Dados!$R:$R,"-") -> 70 | P3: {=_xlfn.LET(_xlpm.t,_xlfn.XLOOKUP(_Shipments[[#This Row],[CLN]],[2]Dados!$D:$D,[2]Dados!$Q:$Q,"-"),_xlfn.IFS(LEFT(_xlpm.t,3)="PAS","Saco",LEFT(_xlpm.t,3)="PBT","Big Bag",TRUE,"-"))} -> Saco | Q3: =_xlfn.LET(_xlpm.p,_xlfn.XLOOKUP(_Shipments[[#This Row],[CLN]],[2]Dados!$D:$D,[2]Dados!$K:$K,"-"),_xlpm.n,_Shipments[[#This Row],[Qtde. sacos/palete]],IF(ISNUMBER(_xlpm.p),IF(_Shipments[[#This Row],[Embalagem]]="Big Bag",IF(ISNUMBER(_xlpm.n),_xlpm.p*_xlpm.n,"-"),_xlpm.p),"-")) -> 13.77 | R3: =IF(_Shipments[[#This Row],[Embalagem]]="Big Bag",_Shipments[[#This Row],[Qtd.]],ROUNDUP(_Shipments[[#This Row],[Qtd.]]/_Shipments[[#This Row],[Qtde. sacos/palete]],0)) -> 1 | S3: ECIO CRISTINO FERREIRA | T3: 34992119997 | U3: QDC-5910 | V3: HJC-1938 | W3: G10 TRANSPORTES S.A | Y3: 7240104
A4: =_xlfn.XLOOKUP(_Shipments[[#This Row],[Shipment]],[1]Report!$G:$G,[1]Report!$B:$B,"-") -> 46260.333 | B4: 7240103 | C4: 5541981925 | D4: 3 | E4: P3845VYHR-B824 | F4: 16 | G4: CORTEVA AGRISCIENCE DO BRASIL LTDA. | H4: APARECIDA DE GOIÂNIA | I4: GO | J4: 16 | K4: 7520951 | L4: 03P7520951 | M4: R2 | N4: =IF(_Shipments[[#This Row],[Embalagem]]="Big Bag",_Shipments[[#This Row],[Qtd.]]*_Shipments[[#This Row],[Qtde. sacos/palete]],_Shipments[[#This Row],[Qtd.]]) -> 16 | O4: =_xlfn.XLOOKUP(_Shipments[[#This Row],[CLN]],[2]Dados!$D:$D,[2]Dados!$R:$R,"-") -> 60 | P4: {=_xlfn.LET(_xlpm.t,_xlfn.XLOOKUP(_Shipments[[#This Row],[CLN]],[2]Dados!$D:$D,[2]Dados!$Q:$Q,"-"),_xlfn.IFS(LEFT(_xlpm.t,3)="PAS","Saco",LEFT(_xlpm.t,3)="PBT","Big Bag",TRUE,"-"))} -> Saco | Q4: =_xlfn.LET(_xlpm.p,_xlfn.XLOOKUP(_Shipments[[#This Row],[CLN]],[2]Dados!$D:$D,[2]Dados!$K:$K,"-"),_xlpm.n,_Shipments[[#This Row],[Qtde. sacos/palete]],IF(ISNUMBER(_xlpm.p),IF(_Shipments[[#This Row],[Embalagem]]="Big Bag",IF(ISNUMBER(_xlpm.n),_xlpm.p*_xlpm.n,"-"),_xlpm.p),"-")) -> 16.69 | R4: =IF(_Shipments[[#This Row],[Embalagem]]="Big Bag",_Shipments[[#This Row],[Qtd.]],ROUNDUP(_Shipments[[#This Row],[Qtd.]]/_Shipments[[#This Row],[Qtde. sacos/palete]],0)) -> 1 | S4: ECIO CRISTINO FERREIRA | T4: 34992119997 | U4: QDC-5910 | V4: HJC-1938 | W4: G10 TRANSPORTES S.A | Y4: 7240105
A5: =_xlfn.XLOOKUP(_Shipments[[#This Row],[Shipment]],[1]Report!$G:$G,[1]Report!$B:$B,"-") -> 46260.333 | B5: 7240103 | C5: 5541981925 | D5: 4 | E5: P3845VYHR-B821 | F5: 27 | G5: CORTEVA AGRISCIENCE DO BRASIL LTDA. | H5: APARECIDA DE GOIÂNIA | I5: GO | J5: 27 | K5: 7520927 | L5: 03P7520927 | M5: C2 | N5: =IF(_Shipments[[#This Row],[Embalagem]]="Big Bag",_Shipments[[#This Row],[Qtd.]]*_Shipments[[#This Row],[Qtde. sacos/palete]],_Shipments[[#This Row],[Qtd.]]) -> 27 | O5: =_xlfn.XLOOKUP(_Shipments[[#This Row],[CLN]],[2]Dados!$D:$D,[2]Dados!$R:$R,"-") -> 60 | P5: {=_xlfn.LET(_xlpm.t,_xlfn.XLOOKUP(_Shipments[[#This Row],[CLN]],[2]Dados!$D:$D,[2]Dados!$Q:$Q,"-"),_xlfn.IFS(LEFT(_xlpm.t,3)="PAS","Saco",LEFT(_xlpm.t,3)="PBT","Big Bag",TRUE,"-"))} -> Saco | Q5: =_xlfn.LET(_xlpm.p,_xlfn.XLOOKUP(_Shipments[[#This Row],[CLN]],[2]Dados!$D:$D,[2]Dados!$K:$K,"-"),_xlpm.n,_Shipments[[#This Row],[Qtde. sacos/palete]],IF(ISNUMBER(_xlpm.p),IF(_Shipments[[#This Row],[Embalagem]]="Big Bag",IF(ISNUMBER(_xlpm.n),_xlpm.p*_xlpm.n,"-"),_xlpm.p),"-")) -> 14.69 | R5: =IF(_Shipments[[#This Row],[Embalagem]]="Big Bag",_Shipments[[#This Row],[Qtd.]],ROUNDUP(_Shipments[[#This Row],[Qtd.]]/_Shipments[[#This Row],[Qtde. sacos/palete]],0)) -> 1 | S5: ECIO CRISTINO FERREIRA | T5: 34992119997 | U5: QDC-5910 | V5: HJC-1938 | W5: G10 TRANSPORTES S.A | Y5: 7240106
